Workbook

Sheet 空白班表
A1: 出貨通知單單別號 | B1: 批號 | C1: 對象簡稱 | D1: 指送地 | E1: 品名 | F1: 預計到貨日期 | G1: 到貨時間 | H1: 運輸方式 | I1: 趟次 | J1: 車牌 | K1: 司機 | L1: 電話 | M1: 出車日期 | N1: 出車時間 | O1: 景山司機代碼
A2: SNXM101-20260701005 | C2: 默克先進 | D2: 萬洲化學 | E2: PMAUPS | F2: 46207 | G2: 07:30 | J2: =IF($O2<>"",VLOOKUP($O2,司機清單!$B$2:$E$59,2,0),"") -> KNB-3277 | K2: =IF($O2<>"",VLOOKUP($O2,司機清單!$B$2:$E$59,3,0),"") -> 方立人 | L2: =IF($O2<>"",VLOOKUP($O2,司機清單!$B$2:$E$59,4,0),"") -> 0903-011-314 | M2: 46206 | N2: 0.10416667 | O2: 39
A3: SNXM101-20260630116 | C3: 默克先進 | D3: 默克二廠 | E3: PMA(A+) | F3: 46207 | G3: 07:30 | J3: =IF($O3<>"",VLOOKUP($O3,司機清單!$B$2:$E$59,2,0),"") -> 079-KP | K3: =IF($O3<>"",VLOOKUP($O3,司機清單!$B$2:$E$59,3,0),"") -> 王東富 | L3: =IF($O3<>"",VLOOKUP($O3,司機清單!$B$2:$E$59,4,0),"") -> 0911-735-595 | M3: 46206 | N3: 0.10416667 | O3: 40
A4: SNXM101-20260701013 | B4: 62714G01/S147 | C4: 默克先進 | D4: 台灣美光晶圓科技股份有限公司F11C. | E4: PMAUPS | F4: 46207 | G4: 04:30 | J4: =IF($O4<>"",VLOOKUP($O4,司機清單!$B$2:$E$59,2,0),"") -> 787-5A | K4: =IF($O4<>"",VLOOKUP($O4,司機清單!$B$2:$E$59,3,0),"") -> 王振勛 | L4: =IF($O4<>"",VLOOKUP($O4,司機清單!$B$2:$E$59,4,0),"") -> 0976-394-788 | M4: 46205 | N4: 0.97916667 | O4: 41
A5: SNXM101-20260630041 | B5: 62715G02/S142 | C5: 默克先進 | D5: 台灣美光記憶體股份有限公司F16A3-M2 | E5: PMAUPS | F5: 46207 | G5: 14:00 | J5: =IF($O5<>"",VLOOKUP($O5,司機清單!$B$2:$E$59,2,0),"") -> 787-5A | K5: =IF($O5<>"",VLOOKUP($O5,司機清單!$B$2:$E$59,3,0),"") -> 王振勛 | L5: =IF($O5<>"",VLOOKUP($O5,司機清單!$B$2:$E$59,4,0),"") -> 0976-394-788 | M5: 46206 | N5: 0.41666667 | O5: 41
A6: SNXM101-20260630071 | B6: 62716G02/S143 | C6: 默克先進 | D6: 台灣美光記憶體股份有限公司F16A2 | E6: PMAUPS | F6: 46207 | G6: 16:30 | J6: =IF($O6<>"",VLOOKUP($O6,司機清單!$B$2:$E$59,2,0),"") -> 787-5A | K6: =IF($O6<>"",VLOOKUP($O6,司機清單!$B$2:$E$59,3,0),"") -> 王振勛 | L6: =IF($O6<>"",VLOOKUP($O6,司機清單!$B$2:$E$59,4,0),"") -> 0976-394-788 | M6: 46206 | N6: 0.52083333 | O6: 41
A7: SNXM101-20260630011 | B7: 62717G02/S141 | C7: 默克先進 | D7: 台灣美光記憶體股份有限公司F16A3-M1.. | E7: PMAUPS | F7: 46207 | G7: 20:00 | J7: =IF($O7<>"",VLOOKUP($O7,司機清單!$B$2:$E$59,2,0),"") -> 787-5A | K7: =IF($O7<>"",VLOOKUP($O7,司機清單!$B$2:$E$59,3,0),"") -> 王振勛 | L7: =IF($O7<>"",VLOOKUP($O7,司機清單!$B$2:$E$59,4,0),"") -> 0976-394-788 | M7: 46206 | N7: 0.66666667 | O7: 41
A8: SNXM101-20260702031 | B8: S09 | C8: 奇美 | D8: 樹谷園區 | E8: PMA(A+) | F8: 46207 | G8: 09:30 | H8: 追加 | J8: 753-5A | K8: 呂育庭 | L8: 0929-762-117 | M8: 46206 | N8: 0.3125 | O8: 60
A9: SNXM101-20260623001 | B9: S47 | C9: 台灣富士電 | D9: 富士電-南科 | E9: SET100 | F9: 46207 | G9: 16:00 | J9: =IF($O9<>"",VLOOKUP($O9,司機清單!$B$2:$E$59,2,0),"") -> KNA-7023 | K9: =IF($O9<>"",VLOOKUP($O9,司機清單!$B$2:$E$59,3,0),"") -> 陳炯嘉 | L9: =IF($O9<>"",VLOOKUP($O9,司機清單!$B$2:$E$59,4,0),"") -> 0988-772-856 | M9: 46206 | N9: 0.58333333 | O9: 60
A10: SNXM101-20260629142 | B10: 26630S183T1 | C10: 台積電 | D10: 龍潭廠 FB30 | E10: CPNE4R | F10: 46207 | G10: 09:00 | H10: 【勝一派技服】 | J10: =IF($O10<>"",VLOOKUP($O10,司機清單!$B$2:$E$59,2,0),"") -> KNA-7009 | K10: =IF($O10<>"",VLOOKUP($O10,司機清單!$B$2:$E$59,3,0),"") -> 黃啟源 | L10: =IF($O10<>"",VLOOKUP($O10,司機清單!$B$2:$E$59,4,0),"") -> 0915-330-169 | M10: 46206 | N10: 0.16666667 | O10: 81
A11: SNXM101-20260624045 | B11: 26630S96T1 | C11: 台積電 | D11: 台積12廠P1 | E11: SEP73E4 | F11: 46207 | G11: 10:00 | H11: 【勝一派技服】 | J11: =IF($O11<>"",VLOOKUP($O11,司機清單!$B$2:$E$59,2,0),"") -> KNA-7009 | K11: =IF($O11<>"",VLOOKUP($O11,司機清單!$B$2:$E$59,3,0),"") -> 黃啟源 | L11: =IF($O11<>"",VLOOKUP($O11,司機清單!$B$2:$E$59,4,0),"") -> 0915-330-169 | M11: 46206 | N11: 0.20833333 | O11: 81
A12: SNXM101-20260526043 | B12: 26701S125T1 | C12: 台積電 | D12: 台積12廠P7 | E12: PMAHQ | F12: 46207 | G12: 16:00 | H12: 【勝一派技服】 | J12: =IF($O12<>"",VLOOKUP($O12,司機清單!$B$2:$E$59,2,0),"") -> KNB-6789 | K12: =IF($O12<>"",VLOOKUP($O12,司機清單!$B$2:$E$59,3,0),"") -> 吳思慶 | L12: =IF($O12<>"",VLOOKUP($O12,司機清單!$B$2:$E$59,4,0),"") -> 0981-125-099 | M12: 46206 | N12: 0.45833333 | O12: 55
A13: SNXM101-20260622221 | B13: 26630S381T1 | C13: 台積電 | D13: 台積寶山廠F20P1 | E13: PMAHQ | F13: 46207 | G13: 22:00 | H13: 【勝一派技服】 | J13: =IF($O13<>"",VLOOKUP($O13,司機清單!$B$2:$E$59,2,0),"") -> KNC-5600 | K13: =IF($O13<>"",VLOOKUP($O13,司機清單!$B$2:$E$59,3,0),"") -> 李冠霆 | L13: =IF($O13<>"",VLOOKUP($O13,司機清單!$B$2:$E$59,4,0),"") -> 0983-792-990 | M13: 46206 | N13: 0.70833333 | O13: 58
A14: SNXM101-20260602134 | B14: 26702S185T1 | C14: 台積電 | D14: 中科A5B0 | E14: CPNE4R | F14: 46207 | G14: 09:00 | H14: 【勝一派技服】 | J14: =IF($O14<>"",VLOOKUP($O14,司機清單!$B$2:$E$59,2,0),"") -> 756-5A | K14: =IF($O14<>"",VLOOKUP($O14,司機清單!$B$2:$E$59,3,0),"") -> 陳明男 | L14: =IF($O14<>"",VLOOKUP($O14,司機清單!$B$2:$E$59,4,0),"") -> 0939-648-289 | M14: 46206 | N14: 0.20833333 | O14: 73
A15: SNXM101-20260610032 | B15: 26630S402T1 | C15: 台積電 | D15: 台積15廠P3 | E15: SEP73E5 | F15: 46207 | G15: 16:00 | H15: 【勝一派技服】 | J15: =IF($O15<>"",VLOOKUP($O15,司機清單!$B$2:$E$59,2,0),"") -> KLK-9122 | K15: =IF($O15<>"",VLOOKUP($O15,司機清單!$B$2:$E$59,3,0),"") -> 陳乾笙 | L15: =IF($O15<>"",VLOOKUP($O15,司機清單!$B$2:$E$59,4,0),"") -> 0979-126-736 | M15: 46206 | N15: 0.5 | O15: 77
A16: SNXM101-20260602067 | B16: 26630S403T1 | C16: 台積電 | D16: 台積15廠P4 | E16: SEP73E5 | F16: 46208 | G16: 16:00 | H16: 【勝一派技服】 | J16: =IF($O16<>"",VLOOKUP($O16,司機清單!$B$2:$E$59,2,0),"") -> KLK-9122 | K16: =IF($O16<>"",VLOOKUP($O16,司機清單!$B$2:$E$59,3,0),"") -> 陳乾笙 | L16: =IF($O16<>"",VLOOKUP($O16,司機清單!$B$2:$E$59,4,0),"") -> 0979-126-736 | M16: 46206 | N16: 0.5 | O16: 77
A17: SNXM101-20260622093 | B17: 26630S164T1 | C17: 台積電 | D17: 台積F15B P5A | E17: SEP73E5 | F17: 46208 | G17: 03:00 | H17: 【勝一派技服】 | J17: =IF($O17<>"",VLOOKUP($O17,司機清單!$B$2:$E$59,2,0),"") -> 079-KP | K17: =IF($O17<>"",VLOOKUP($O17,司機清單!$B$2:$E$59,3,0),"") -> 王東富 | L17: =IF($O17<>"",VLOOKUP($O17,司機清單!$B$2:$E$59,4,0),"") -> 0911-735-595 | M17: 46205 | N17: 0.95833333 | O17: 40
A18: SNXM101-20260622094 | B18: 26630S177T1 | C18: 台積電 | D18: 台積F15B P5A | E18: SEP73E5 | F18: 46208 | G18: 22:00 | H18: 【勝一派技服】 | J18: =IF($O18<>"",VLOOKUP($O18,司機清單!$B$2:$E$59,2,0),"") -> 787-5A | K18: =IF($O18<>"",VLOOKUP($O18,司機清單!$B$2:$E$59,3,0),"") -> 王振勛 | L18: =IF($O18<>"",VLOOKUP($O18,司機清單!$B$2:$E$59,4,0),"") -> 0976-394-788 | M18: 46206 | N18: 0.75 | O18: 41
A19: SNXM101-20260618036 | B19: 26630S158T1 | C19: 台積電 | D19: 台積中科15廠P6 | E19: SEP73E5 | F19: 46208 | G19: 07:00 | H19: 【勝一派技服】 | J19: =IF($O19<>"",VLOOKUP($O19,司機清單!$B$2:$E$59,2,0),"") -> KNB-8313 | K19: =IF($O19<>"",VLOOKUP($O19,司機清單!$B$2:$E$59,3,0),"") -> 謝明輝 | L19: =IF($O19<>"",VLOOKUP($O19,司機清單!$B$2:$E$59,4,0),"") -> 0903-671-388 | M19: 46206 | N19: 0.125 | O19: 54
A20: SNXM101-20260602114 | B20: 26630S196T1 | C20: 台積電 | D20: 台積15廠P7 | E20: SEP73E5 | F20: 46208 | G20: 00:00 | H20: 【勝一派技服】 | J20: =IF($O20<>"",VLOOKUP($O20,司機清單!$B$2:$E$59,2,0),"") -> KNB-8313 | K20: =IF($O20<>"",VLOOKUP($O20,司機清單!$B$2:$E$59,3,0),"") -> 謝明輝 | L20: =IF($O20<>"",VLOOKUP($O20,司機清單!$B$2:$E$59,4,0),"") -> 0903-671-388 | M20: 46205 | N20: 0.83333333 | O20: 54
A21: SNXM101-20260602115 | B21: 26630S195T1 | C21: 台積電 | D21: 台積15廠P7 | E21: SEP73E5 | F21: 46208 | G21: 19:00 | H21: 【勝一派技服】 | J21: =IF($O21<>"",VLOOKUP($O21,司機清單!$B$2:$E$59,2,0),"") -> KNC-8667 | K21: =IF($O21<>"",VLOOKUP($O21,司機清單!$B$2:$E$59,3,0),"") -> 薛智平 | L21: =IF($O21<>"",VLOOKUP($O21,司機清單!$B$2:$E$59,4,0),"") -> 0903-725-955 | M21: 46206 | N21: 0.625 | O21: 106
... A31: SNXM101-20260602161 | B31: 26701S121T1 | C31: 台積電 | D31: 台積18廠P7 | E31: PMAHQ | F31: 46207 | G31: 16:00 | H31: 【勝一派技服】 | J31: =IF($O31<>"",VLOOKUP($O31,司機清單!$B$2:$E$59,2,0),"") -> KNB-3277 | K31: =IF($O31<>"",VLOOKUP($O31,司機清單!$B$2:$E$59,3,0),"") -> 方立人 | L31: =IF($O31<>"",VLOOKUP($O31,司機清單!$B$2:$E$59,4,0),"") -> 0903-011-314 | M31: 46206 | N31: 0.58333333 | O31: 39
D32: 鴻勝 > 路竹 | E32: MEA | F32: 46207 | G32: 16:00 | H32: E-46 | J32: =IF($O32<>"",VLOOKUP($O32,司機清單!$B$2:$E$59,2,0),"") -> 083-KP | K32: =IF($O32<>"",VLOOKUP($O32,司機清單!$B$2:$E$59,3,0),"") -> 嚴進吉 | L32: =IF($O32<>"",VLOOKUP($O32,司機清單!$B$2:$E$59,4,0),"") -> 0936-114-978 | M32: 46206 | N32: 0.54166667 | O32: 92
D33: 勝一 > 鴻勝 > 勝一 | E33: CPN | F33: 46207 | G33: 09:00 | H33: S-79 | J33: =IF($O33<>"",VLOOKUP($O33,司機清單!$B$2:$E$59,2,0),"") -> KNB-8313 | K33: =IF($O33<>"",VLOOKUP($O33,司機清單!$B$2:$E$59,3,0),"") -> 謝明輝 | L33: =IF($O33<>"",VLOOKUP($O33,司機清單!$B$2:$E$59,4,0),"") -> 0903-671-388 | M33: 46206 | N33: 0.25 | O33: 54
D34: 勝一 > 鴻勝 > 勝一 | E34: CPN | F34: 46207 | G34: 13:00 | H34: S-223 | J34: =IF($O34<>"",VLOOKUP($O34,司機清單!$B$2:$E$59,2,0),"") -> KNB-9526 | K34: =IF($O34<>"",VLOOKUP($O34,司機清單!$B$2:$E$59,3,0),"") -> 蕭家瑧 | L34: =IF($O34<>"",VLOOKUP($O34,司機清單!$B$2:$E$59,4,0),"") -> 0927-077-808 | M34: 46206 | N34: 0.41666667 | O34: 88
D35: 駐廠-研製 | F35: 12:00-20:00 | J35: =IF($O35<>"",VLOOKUP($O35,司機清單!$B$2:$E$59,2,0),"") -> KNA-3538 | K35: =IF($O35<>"",VLOOKUP($O35,司機清單!$B$2:$E$59,3,0),"") -> 顏禎慶 | L35: =IF($O35<>"",VLOOKUP($O35,司機清單!$B$2:$E$59,4,0),"") -> 0976-923-831 | M35: 46206 | O35: 98
D36: 駐廠-(一) | F36: 07:00-16:00 | J36: =IF($O36<>"",VLOOKUP($O36,司機清單!$B$2:$E$59,2,0),"") -> KNA-3537 | K36: =IF($O36<>"",VLOOKUP($O36,司機清單!$B$2:$E$59,3,0),"") -> 余俊雄 | L36: =IF($O36<>"",VLOOKUP($O36,司機清單!$B$2:$E$59,4,0),"") -> 0915-797-299 | M36: 46206 | O36: 79
D37: 駐廠-(二) | F37: 07:00-16:00 | J37: =IF($O37<>"",VLOOKUP($O37,司機清單!$B$2:$E$59,2,0),"") -> KNA-3017 | K37: =IF($O37<>"",VLOOKUP($O37,司機清單!$B$2:$E$59,3,0),"") -> 翁仁貴 | L37: =IF($O37<>"",VLOOKUP($O37,司機清單!$B$2:$E$59,4,0),"") -> 0937-646-148 | M37: 46206 | O37: 105
D38: 駐廠-(一) | F38: 16:00-00:00 | J38: =IF($O38<>"",VLOOKUP($O38,司機清單!$B$2:$E$59,2,0),"") -> 376-KP | K38: =IF($O38<>"",VLOOKUP($O38,司機清單!$B$2:$E$59,3,0),"") -> 蔡文安 | L38: =IF($O38<>"",VLOOKUP($O38,司機清單!$B$2:$E$59,4,0),"") -> 0932-998-138 | M38: 46206 | O38: 95
D39: 駐廠-(二) | F39: 16:00-00:00 | J39: =IF($O39<>"",VLOOKUP($O39,司機清單!$B$2:$E$59,2,0),"") -> KNB-3175 | K39: =IF($O39<>"",VLOOKUP($O39,司機清單!$B$2:$E$59,3,0),"") -> 黃偉亮 | L39: =IF($O39<>"",VLOOKUP($O39,司機清單!$B$2:$E$59,4,0),"") -> 0909-796-597 | M39: 46206 | O39: 80
D40: 駐廠-大夜 | F40: 00:00-08:00 | J40: =IF($O40<>"",VLOOKUP($O40,司機清單!$B$2:$E$59,2,0),"") -> 786-5A | K40: =IF($O40<>"",VLOOKUP($O40,司機清單!$B$2:$E$59,3,0),"") -> 林介文 | L40: =IF($O40<>"",VLOOKUP($O40,司機清單!$B$2:$E$59,4,0),"") -> 0935-454-865 | M40: 46206 | O40: 61
D41: 駐廠-資材 | F41: 08:00-17:00 | J41: =IF($O41<>"",VLOOKUP($O41,司機清單!$B$2:$E$59,2,0),"") -> KNA-3552 | K41: =IF($O41<>"",VLOOKUP($O41,司機清單!$B$2:$E$59,3,0),"") -> 楊達文 | L41: =IF($O41<>"",VLOOKUP($O41,司機清單!$B$2:$E$59,4,0),"") -> 0908-520-916 | M41: 46206 | O41: 96
A42: SNXM101-20260618107 | B42: 26702S83T1 | C42: 台積電 | D42: 台積電14廠-P3 | E42: SEP73E4 | F42: 46206 | G42: 19:00 | H42: 追加 | J42: KLK-9122 | K42: 陳乾笙 | L42: 0979-126-736 | M42: 46206 | N42: 0.70833333 | O42: 77
D43: 駐廠-資材 | F43: 08:00-17:00 | H43: 追加 | J43: KNA-3536 | K43: 黃新全 | L43: 0987-865-686 | M43: 46206
J44: =IF($O44<>"",VLOOKUP($O44,司機清單!$B$2:$E$59,2,0),"") | K44: =IF($O44<>"",VLOOKUP($O44,司機清單!$B$2:$E$59,3,0),"") | L44: =IF($O44<>"",VLOOKUP($O44,司機清單!$B$2:$E$59,4,0),"")
J45: =IF($O45<>"",VLOOKUP($O45,司機清單!$B$2:$E$59,2,0),"") | K45: =IF($O45<>"",VLOOKUP($O45,司機清單!$B$2:$E$59,3,0),"") | L45: =IF($O45<>"",VLOOKUP($O45,司機清單!$B$2:$E$59,4,0),"")
J46: =IF($O46<>"",VLOOKUP($O46,司機清單!$B$2:$E$59,2,0),"") | K46: =IF($O46<>"",VLOOKUP($O46,司機清單!$B$2:$E$59,3,0),"") | L46: =IF($O46<>"",VLOOKUP($O46,司機清單!$B$2:$E$59,4,0),"")
J47: =IF($O47<>"",VLOOKUP($O47,司機清單!$B$2:$E$59,2,0),"") | K47: =IF($O47<>"",VLOOKUP($O47,司機清單!$B$2:$E$59,3,0),"") | L47: =IF($O47<>"",VLOOKUP($O47,司機清單!$B$2:$E$59,4,0),"")
J48: =IF($O48<>"",VLOOKUP($O48,司機清單!$B$2:$E$59,2,0),"") | K48: =IF($O48<>"",VLOOKUP($O48,司機清單!$B$2:$E$59,3,0),"") | L48: =IF($O48<>"",VLOOKUP($O48,司機清單!$B$2:$E$59,4,0),"")
J49: =IF($O49<>"",VLOOKUP($O49,司機清單!$B$2:$E$59,2,0),"") | K49: =IF($O49<>"",VLOOKUP($O49,司機清單!$B$2:$E$59,3,0),"") | L49: =IF($O49<>"",VLOOKUP($O49,司機清單!$B$2:$E$59,4,0),"")
...

Sheet 司機清單
B2: 39 | C2: KNB-3277 | D2: 方立人 | E2: 0903-011-314 | F2: E-0847450
B3: 40 | C3: 079-KP | D3: 王東富 | E3: 0911-735-595 | F3: S-5329540
B4: 41 | C4: 787-5A | D4: 王振勛 | E4: 0976-394-788 | F4: E-7516900
B5: 42 | C5: KNB-3532 | D5: 余智緯 | E5: 0983-001-400 | F5: S-6157380
B6: 54 | C6: KNB-8313 | D6: 謝明輝 | E6: 0903-671-388
B7: 55 | C7: KNB-6789 | D7: 吳思慶 | E7: 0981-125-099 | F7: S-3725320
B8: 56 | C8: 753-5A | D8: 呂育庭 | E8: 0929-762-117 | F8: S-5078440
B9: 57 | C9: KNA-7237 | D9: 宋志祥 | E9: 0931-068-752 | F9: S-8837560
B10: 58 | C10: KNC-5600 | D10: 李冠霆 | E10: 0983-792-990 | F10: S9267120
B11: 59 | C11: KNB-8855 | D11: 李奕德 | E11: 0956-002-021 | F11: S-4526150
B12: 60 | C12: KNA-7023 | D12: 陳炯嘉 | E12: 0988-772-856
B13: 61 | C13: 786-5A | D13: 林介文 | E13: 0935-454-865 | F13: R-5875250
B14: 62 | C14: HAA-875 | D14: 林宏奕 | E14: 0960-090-122 | F14: E-8446560
B15: 63 | C15: HAB-898 | D15: 林沛鋒 | E15: 0982-536-929 | F15: D-3050350
B16: 64 | C16: 080-KP | D16: 林宗信 | E16: 0929-097-972 | F16: Q-7497880
B17: 65 | C17: 757-5A | D17: 林俊銘 | E17: 0927-977-812 | F17: R-0677400
B18: 66 | C18: KNB-3176 | D18: 邱信華 | E18: 0930-591-160 | F18: T-2047090
B19: 67 | C19: 785-5A | D19: 胡碩寬 | E19: 0927-572-879 | F19: R-9234720
B20: 68 | C20: KNB-9529 | D20: 高志強 | E20: 0978-215-787 | F20: T7340750
B21: 69 | C21: 788-5A | D21: 高宥棋 | E21: 0929-007-134 | F21: D-9956510
B22: 70 | C22: 758-5A | D22: 張國發 | E22: 0955-604-174 | F22: Q-2950250
B23: 71 | C23: KNB-3120 | D23: 黃冠毓 | E23: 0981-733-022
B24: 72 | C24: KNA-3686 | D24: 劉嘉慶 | E24: 0933-685-930
B25: 73 | C25: 756-5A | D25: 陳明男 | E25: 0939-648-289 | F25: Q-4139630
B26: 74 | C26: KNA-3551 | D26: 陳彥吉 | E26: 0915-264-905 | F26: R-7240880
B27: 75 | C27: 062-KP | D27: 陳皇賓 | E27: 0916-870-575 | F27: E9018320
B28: 76 | C28: KNB-9591 | D28: 陳高煒 | E28: 0981-056-333 | F28: T2175280
B29: 77 | C29: KLK-9122 | D29: 陳乾笙 | E29: 0979-126-736 | F29: D-1334860
B30: 78 | C30: HAA-816 | D30: 陳義興 | E30: 0931-960-540
B31: 79 | C31: KNA-3537 | D31: 余俊雄 | E31: 0915-797-299
B32: 80 | C32: KNB-3175 | D32: 黃偉亮 | E32: 0909-796-597 | F32: S-7106030
B33: 81 | C33: KNA-7009 | D33: 黃啟源 | E33: 0915-330-169 | F33: S-8458980
B34: 82 | C34: KNB-3067 | D34: 黃進武 | E34: 0925-162-221 | F34: T6115800
B35: 83 | C35: KLN-5081 | D35: 黃誌誠 | E35: 0933-376-055 | F35: S-7258750
B36: 84 | C36: KLN-8263 | D36: 楊裕賢 | E36: 0976-268-708 | F36: S-0687590
B37: 85 | C37: 783-5A | D37: 詹添福 | E37: 0970-668-709 | F37: S-1404780
B38: 86 | C38: 063-KP | D38: 蔡侑廷 | E38: 0912-119-124 | F38: S-3762050
B39: 87 | C39: KNA-7238 | D39: 鄧鈞天 | E39: 0989-219-271 | F39: S-2993340
B40: 88 | C40: KNB-9526 | D40: 蕭家瑧 | E40: 0927-077-808 | F40: E1362840
B41: 89 | C41: 628-ZB | D41: 蘇政誌 | E41: 0982-644-543 | F41: R8594480
...

Sheet 空白
A1: 批號 | B1: 對象簡稱 | C1: 指送地 | D1: 品名 | E1: 預計到貨日期 | F1: 到貨時間 | G1: 運輸方式 | H1: 趟次 | I1: 車牌 | J1: 司機 | K1: 電話 | L1: 出車日期 | M1: 出車時間 | N1: 備註 | O1: 景山司機代碼
I2: =IF($O2<>"",VLOOKUP($O2,司機清單!$B$2:$E$59,2,0),"") | J2: =IF($O2<>"",VLOOKUP($O2,司機清單!$B$2:$E$59,3,0),"") | K2: =IF($O2<>"",VLOOKUP($O2,司機清單!$B$2:$E$59,4,0),"")
I3: =IF($O3<>"",VLOOKUP($O3,司機清單!$B$2:$E$59,2,0),"") | J3: =IF($O3<>"",VLOOKUP($O3,司機清單!$B$2:$E$59,3,0),"") | K3: =IF($O3<>"",VLOOKUP($O3,司機清單!$B$2:$E$59,4,0),"")
I4: =IF($O4<>"",VLOOKUP($O4,司機清單!$B$2:$E$59,2,0),"") | J4: =IF($O4<>"",VLOOKUP($O4,司機清單!$B$2:$E$59,3,0),"") | K4: =IF($O4<>"",VLOOKUP($O4,司機清單!$B$2:$E$59,4,0),"")
I5: =IF($O5<>"",VLOOKUP($O5,司機清單!$B$2:$E$59,2,0),"") | J5: =IF($O5<>"",VLOOKUP($O5,司機清單!$B$2:$E$59,3,0),"") | K5: =IF($O5<>"",VLOOKUP($O5,司機清單!$B$2:$E$59,4,0),"")
I6: =IF($O6<>"",VLOOKUP($O6,司機清單!$B$2:$E$59,2,0),"") | J6: =IF($O6<>"",VLOOKUP($O6,司機清單!$B$2:$E$59,3,0),"") | K6: =IF($O6<>"",VLOOKUP($O6,司機清單!$B$2:$E$59,4,0),"")
I7: =IF($O7<>"",VLOOKUP($O7,司機清單!$B$2:$E$59,2,0),"") | J7: =IF($O7<>"",VLOOKUP($O7,司機清單!$B$2:$E$59,3,0),"") | K7: =IF($O7<>"",VLOOKUP($O7,司機清單!$B$2:$E$59,4,0),"")
I8: =IF($O8<>"",VLOOKUP($O8,司機清單!$B$2:$E$59,2,0),"") | J8: =IF($O8<>"",VLOOKUP($O8,司機清單!$B$2:$E$59,3,0),"") | K8: =IF($O8<>"",VLOOKUP($O8,司機清單!$B$2:$E$59,4,0),"")
I9: =IF($O9<>"",VLOOKUP($O9,司機清單!$B$2:$E$59,2,0),"") | J9: =IF($O9<>"",VLOOKUP($O9,司機清單!$B$2:$E$59,3,0),"") | K9: =IF($O9<>"",VLOOKUP($O9,司機清單!$B$2:$E$59,4,0),"")
I10: =IF($O10<>"",VLOOKUP($O10,司機清單!$B$2:$E$59,2,0),"") | J10: =IF($O10<>"",VLOOKUP($O10,司機清單!$B$2:$E$59,3,0),"") | K10: =IF($O10<>"",VLOOKUP($O10,司機清單!$B$2:$E$59,4,0),"")
I11: =IF($O11<>"",VLOOKUP($O11,司機清單!$B$2:$E$59,2,0),"") | J11: =IF($O11<>"",VLOOKUP($O11,司機清單!$B$2:$E$59,3,0),"") | K11: =IF($O11<>"",VLOOKUP($O11,司機清單!$B$2:$E$59,4,0),"")
I12: =IF($O12<>"",VLOOKUP($O12,司機清單!$B$2:$E$59,2,0),"") | J12: =IF($O12<>"",VLOOKUP($O12,司機清單!$B$2:$E$59,3,0),"") | K12: =IF($O12<>"",VLOOKUP($O12,司機清單!$B$2:$E$59,4,0),"")
I13: =IF($O13<>"",VLOOKUP($O13,司機清單!$B$2:$E$59,2,0),"") | J13: =IF($O13<>"",VLOOKUP($O13,司機清單!$B$2:$E$59,3,0),"") | K13: =IF($O13<>"",VLOOKUP($O13,司機清單!$B$2:$E$59,4,0),"")
... I623: =IF($O623<>"",VLOOKUP($O623,司機清單!$B$2:$E$59,2,0),"") | J623: =IF($O623<>"",VLOOKUP($O623,司機清單!$B$2:$E$59,3,0),"") | K623: =IF($O623<>"",VLOOKUP($O623,司機清單!$B$2:$E$59,4,0),"")
