Workbook

Sheet 產銷總表 
A1: 鴻勝化學科技股份有限公司
A2: 產銷計劃表
A3: 單位：MT | AE3: =精餾產銷!$AE$2 -> 日期：2026/08/24
A4: 成品品名 | B4: 存放位置 (隱藏) | C4: =精餾產銷!C3 -> 儲槽 容量 (MT) | D4: =精餾產銷!D3 -> 資材 | E4: =精餾產銷!E3 -> 製2 | F4: =精餾產銷!F3 -> 桶底 | G4: =精餾產銷!G3 -> 46258 | H4: =精餾產銷!H3 -> 08/24~08/31 | J4: =精餾產銷!J3 -> 46295 | L4: =精餾產銷!L3 -> 46326 | N4: =精餾產銷!N3 -> 46356 | P4: =精餾產銷!P3 -> 生產量 | AB4: =精餾產銷!AB3 -> 庫存
D5: =精餾產銷!D4 -> 庫存 | E5: =精餾產銷!E4 -> 庫存 | F5: =精餾產銷!F4 -> 0 | H5: =精餾產銷!H4 -> 銷售 | I5: =精餾產銷!I4 -> 耗用 | J5: =精餾產銷!J4 -> 銷售 | K5: =精餾產銷!K4 -> 耗用 | L5: =精餾產銷!L4 -> 銷售 | M5: =精餾產銷!M4 -> 耗用 | N5: =精餾產銷!N4 -> 銷售 | O5: =精餾產銷!O4 -> 耗用 | P5: =精餾產銷!P4 -> 24~31 | R5: =精餾產銷!R4 -> 數量 | S5: =精餾產銷!S4 -> 9月 | U5: =精餾產銷!U4 -> 數量 | V5: =精餾產銷!V4 -> 10月 | X5: =精餾產銷!X4 -> 數量 | Y5: =精餾產銷!Y4 -> 11月 | AA5: =精餾產銷!AA4 -> 數量 | AB5: =精餾產銷!AB4 -> 8/31 | AC5: =精餾產銷!AC4 -> 46295 | AD5: =精餾產銷!AD4 -> 46326 | AE5: =精餾產銷!AE4 -> 46356 | AH5: 安全存量 | AI5: 安全存量佔儲槽比例 | AJ5: 安全存量佔銷售比例
A6: =精餾產銷!A5 -> IPAUPS | B6: =精餾產銷!B5 -> TK624.TK672.E68.小包 | C6: =精餾產銷!C5 -> 455 | D6: =精餾產銷!D5 -> 100.341 | E6: =精餾產銷!E5 -> 0 | F6: =精餾產銷!F5 -> 25 | G6: =精餾產銷!G5 -> 75.341 | H6: =精餾產銷!H5 -> 0 | ... AE6: =精餾產銷!AE5 -> 75.341 | AF6: =+IF(SUM(G6,H6:O6,R6,U6,X6,AA6)=0,0,1) -> 1 | AH6: =精餾產銷!AH5 -> 150 | AI6: =IF(AH6=0,0,AH6/C6) -> 0.32967033 | AJ6: =IF(AH6=0,0,AH6/((H6+J6+L6+N6)/4)) -> #DIV/0!
A7: =精餾產銷!A6 -> 0 | C7: =精餾產銷!C6 -> 0 | G7: =精餾產銷!G6 -> 0 | H7: =精餾產銷!H6 -> 0 | I7: =精餾產銷!I6 -> 0 | J7: =精餾產銷!J6 -> 0 | K7: =精餾產銷!K6 -> 0 | L7: =精餾產銷!L6 -> 0 | M7: =精餾產銷!M6 -> 0 | N7: =精餾產銷!N6 -> 0 | ... AE7: =精餾產銷!AE6 -> 0 | AF7: =+IF(SUM(G7,H7:O7,R7,U7,X7,AA7)=0,0,1) -> 0 | AH7: =精餾產銷!AH6 -> 0 | AI7: =IF(AH7=0,0,AH7/C7) -> 0 | AJ7: =IF(AH7=0,0,AH7/((H7+J7+L7+N7)/4)) -> 0
A8: =精餾產銷!A7 -> IPAUPS | C8: =精餾產銷!C7 -> 0 | D8: =精餾產銷!D7 -> 0 | E8: =精餾產銷!E7 -> 0 | F8: =精餾產銷!F7 -> 0 | G8: =精餾產銷!G7 -> 0 | H8: =精餾產銷!H7 -> 0 | I8: =精餾產銷!I7 -> 0 | J8: =精餾產銷!J7 -> 0 | ... AE8: =精餾產銷!AE7 -> 0 | AF8: =+IF(SUM(G8,H8:O8,R8,U8,X8,AA8)=0,0,1) -> 0 | AH8: =精餾產銷!AH7 -> 0 | AI8: =IF(AH8=0,0,AH8/C8) -> 0 | AJ8: =IF(AH8=0,0,AH8/((H8+J8+L8+N8)/4)) -> 0
A9: =精餾產銷!A8 -> IPAUPS(崙尾區日本料) | B9: =精餾產銷!B8 -> 0 | C9: =精餾產銷!C8 -> 0 | D9: =精餾產銷!D8 -> 0 | E9: =精餾產銷!E8 -> 0 | F9: =精餾產銷!F8 -> 0 | G9: =精餾產銷!G8 -> 0 | H9: =精餾產銷!H8 -> 0 | ... AE9: =精餾產銷!AE8 -> 0 | AF9: =+IF(SUM(G9,H9:O9,R9,U9,X9,AA9)=0,0,1) -> 1 | AH9: =精餾產銷!AH8 -> 0 | AI9: =IF(AH9=0,0,AH9/C9) -> 0 | AJ9: =IF(AH9=0,0,AH9/((H9+J9+L9+N9)/4)) -> 0
A10: =精餾產銷!A9 -> IPAUPS(崙尾區LG) | B10: =精餾產銷!B9 -> 0 | C10: =精餾產銷!C9 -> 0 | D10: =精餾產銷!D9 -> 101.2 | E10: =精餾產銷!E9 -> 0 | F10: =精餾產銷!F9 -> 0 | G10: =精餾產銷!G9 -> 101.2 | H10: =精餾產銷!H9 -> 266 | ... AE10: =精餾產銷!AE9 -> 970.2 | AF10: =+IF(SUM(G10,H10:O10,R10,U10,X10,AA10)=0,0,1) -> 1 | AH10: =精餾產銷!AH9 -> 0 | AI10: =IF(AH10=0,0,AH10/C10) -> 0 | AJ10: =IF(AH10=0,0,AH10/((H10+J10+L10+N10)/4)) -> 0
A11: =精餾產銷!A10 -> IPAHQ | B11: =精餾產銷!B10 -> TK-681&TK-682 | C11: =精餾產銷!C10 -> 156 | D11: =精餾產銷!D10 -> 91.5 | E11: =精餾產銷!E10 -> 0 | F11: =精餾產銷!F10 -> 0 | G11: =精餾產銷!G10 -> 91.5 | H11: =精餾產銷!H10 -> 140 | ... AE11: =精餾產銷!AE10 -> 1024.5 | AF11: =+IF(SUM(G11,H11:O11,R11,U11,X11,AA11)=0,0,1) -> 1 | AH11: =精餾產銷!AH10 -> 40 | AI11: =IF(AH11=0,0,AH11/C11) -> 0.25641026 | AJ11: =IF(AH11=0,0,AH11/((H11+J11+L11+N11)/4)) -> 0.082474227
A12: =精餾產銷!A11 -> EGUPS | B12: =精餾產銷!B11 -> TK623.E40.E48.E56.E59.E60.E66.E67(E21 外部鏽蝕處理中).TK692.TK689 | C12: =精餾產銷!C11 -> 537 | D12: =精餾產銷!#REF! -> #REF! | E12: =精餾產銷!E11 -> 0 | F12: =精餾產銷!F11 -> 14 | G12: =精餾產銷!G11 -> 6.9 | H12: =精餾產銷!H11 -> 5 | I12: =精餾產銷!I11 -> 52.436 | J12: =精餾產銷!J11 -> 20 | K12: =精餾產銷!K11 -> 291.005 | L12: =精餾產銷!L11 -> 20 | ... AE12: =精餾產銷!AE11 -> 801.449 | AF12: =+IF(SUM(G12,H12:O12,R12,U12,X12,AA12)=0,0,1) -> 1 | AH12: =精餾產銷!AH11 -> 24.94 | AI12: =IF(AH12=0,0,AH12/C12) -> 0.046443203 | AJ12: =IF(AH12=0,0,AH12/((H12+J12+L12+N12)/4)) -> 1.5347692
A13: =精餾產銷!A12 -> EGUPS(勝一S07) | B13: =精餾產銷!B12 -> 0 | C13: =精餾產銷!C12 -> 0 | D13: =精餾產銷!D12 -> 0 | E13: =精餾產銷!E12 -> 0 | F13: =精餾產銷!F12 -> 0 | G13: =精餾產銷!G12 -> 0 | H13: =精餾產銷!H12 -> 0 | ... AE13: =精餾產銷!AE12 -> 0 | AF13: =+IF(SUM(G13,H13:O13,R13,U13,X13,AA13)=0,0,1) -> 1 | AH13: =精餾產銷!AH12 -> 0 | AI13: =IF(AH13=0,0,AH13/C13) -> 0 | AJ13: =IF(AH13=0,0,AH13/((H13+J13+L13+N13)/4)) -> 0
A14: =精餾產銷!A13 -> EGUPS(EG-C) | B14: =精餾產銷!B13 -> TK689 | C14: =精餾產銷!C13 -> 0 | D14: =精餾產銷!D11 -> 20.9 | E14: =精餾產銷!E13 -> 0 | F14: =精餾產銷!F13 -> 0 | G14: =精餾產銷!G13 -> 0 | H14: =精餾產銷!H13 -> 0 | I14: =精餾產銷!I13 -> 0 | J14: =精餾產銷!J13 -> 0 | K14: =精餾產銷!K13 -> 0 | L14: =精餾產銷!L13 -> 0 | ... AE14: =精餾產銷!AE13 -> 0 | AF14: =+IF(SUM(G14,H14:O14,R14,U14,X14,AA14)=0,0,1) -> 0 | AI14: =IF(AH14=0,0,AH14/C14) -> 0 | AJ14: =IF(AH14=0,0,AH14/((H14+J14+L14+N14)/4)) -> 0
A15: =精餾產銷!A16 -> CPNE4 | B15: =精餾產銷!B16 -> TK677&TK680&勝一 | C15: =精餾產銷!C16 -> 355 | D15: =精餾產銷!D16 -> 22 | E15: =精餾產銷!E16 -> 0 | F15: =精餾產銷!F16 -> 21 | G15: =精餾產銷!G16 -> 1 | H15: =精餾產銷!H16 -> 130 | ... AE15: =精餾產銷!AE16 -> -9 | AF15: =+IF(SUM(G15,H15:O15,R15,U15,X15,AA15)=0,0,1) -> 1 | AH15: =精餾產銷!AH16 -> 90 | AI15: =IF(AH15=0,0,AH15/C15) -> 0.25352113 | AJ15: =IF(AH15=0,0,AH15/((H15+J15+L15+N15)/4)) -> 0.34951456
A16: =精餾產銷!A14 -> CPNE4(含浸) | B16: =精餾產銷!B14 -> TK677&TK680 | C16: =精餾產銷!C14 -> 72 | D16: =精餾產銷!D14 -> 0 | E16: =精餾產銷!E14 -> 0 | F16: =精餾產銷!F14 -> 0 | G16: =精餾產銷!G14 -> 0 | H16: =精餾產銷!H14 -> 0 | ... AE16: =精餾產銷!AE14 -> 0 | AF16: =+IF(SUM(G16,H16:O16,R16,U16,X16,AA16)=0,0,1) -> 0 | AH16: =精餾產銷!AH14 -> 0 | AI16: =IF(AH16=0,0,AH16/C16) -> 0 | AJ16: =IF(AH16=0,0,AH16/((H16+J16+L16+N16)/4)) -> 0
A17: =精餾產銷!A15 -> CPNE4R(含浸) | B17: =精餾產銷!B15 -> TK694 | C17: =精餾產銷!C15 -> 230 | D17: =精餾產銷!D15 -> 0 | E17: =精餾產銷!E15 -> 0 | F17: =精餾產銷!F15 -> 1 | G17: =精餾產銷!G15 -> 0 | H17: =精餾產銷!H15 -> 0 | ... AE17: =精餾產銷!AE15 -> 0 | AF17: =+IF(SUM(G17,H17:O17,R17,U17,X17,AA17)=0,0,1) -> 0 | AH17: =精餾產銷!AH15 -> 0 | AI17: =IF(AH17=0,0,AH17/C17) -> 0 | AJ17: =IF(AH17=0,0,AH17/((H17+J17+L17+N17)/4)) -> 0
A18: =精餾產銷!A17 -> ACTUPS | B18: =精餾產銷!B17 -> TK622.TK612.包材 | C18: =精餾產銷!C17 -> 192 | D18: =精餾產銷!D17 -> 110.868 | E18: =精餾產銷!E17 -> 0 | F18: =精餾產銷!F17 -> 17 | G18: =精餾產銷!G17 -> 93.868 | H18: =精餾產銷!H17 -> 5 | ... AE18: =精餾產銷!AE17 -> 148.868 | AF18: =+IF(SUM(G18,H18:O18,R18,U18,X18,AA18)=0,0,1) -> 1 | AH18: =精餾產銷!AH17 -> 35.2 | AI18: =IF(AH18=0,0,AH18/C18) -> 0.18333333 | AJ18: =IF(AH18=0,0,AH18/((H18+J18+L18+N18)/4)) -> 0.9083871
A19: =精餾產銷!A18 -> 外購 | B19: =精餾產銷!B18 -> 0 | C19: =精餾產銷!C18 -> 0 | D19: =精餾產銷!D18 -> 0 | E19: =精餾產銷!E18 -> 0 | F19: =精餾產銷!F18 -> 0 | G19: =精餾產銷!G18 -> 0 | H19: =精餾產銷!H18 -> 0 | ... AE19: =精餾產銷!AE18 -> 0 | AF19: =+IF(SUM(G19,H19:O19,R19,U19,X19,AA19)=0,0,1) -> 0 | AH19: =精餾產銷!AH18 -> 0 | AI19: =IF(AH19=0,0,AH19/C19) -> 0 | AJ19: =IF(AH19=0,0,AH19/((H19+J19+L19+N19)/4)) -> 0
A20: =精餾產銷!A19 -> NMPUPS | B20: =精餾產銷!B19 -> TK621.E58.E26.E31.包材 | C20: =精餾產銷!C19 -> 243.5 | D20: =精餾產銷!D19 -> 148.9 | E20: =精餾產銷!E19 -> 10 | F20: =精餾產銷!F19 -> 15 | G20: =精餾產銷!G19 -> 143.9 | H20: =精餾產銷!H19 -> 0 | ... AE20: =精餾產銷!AE19 -> 29.9 | AF20: =+IF(SUM(G20,H20:O20,R20,U20,X20,AA20)=0,0,1) -> 1 | AH20: =精餾產銷!AH19 -> 46.2 | AI20: =IF(AH20=0,0,AH20/C20) -> 0.18973306 | AJ20: =IF(AH20=0,0,AH20/((H20+J20+L20+N20)/4)) -> 1.6210526
A21: =精餾產銷!A20 -> 外購 | B21: =精餾產銷!B20 -> 0 | C21: =精餾產銷!C20 -> 0 | D21: =精餾產銷!D20 -> 0 | E21: =精餾產銷!E20 -> 0 | F21: =精餾產銷!F20 -> 0 | G21: =精餾產銷!G20 -> 0 | H21: =精餾產銷!H20 -> 0 | ... AE21: =精餾產銷!AE20 -> 0 | AF21: =+IF(SUM(G21,H21:O21,R21,U21,X21,AA21)=0,0,1) -> 0 | AH21: =精餾產銷!AH20 -> 0 | AI21: =IF(AH21=0,0,AH21/C21) -> 0 | AJ21: =IF(AH21=0,0,AH21/((H21+J21+L21+N21)/4)) -> 0
A22: =精餾產銷!A21 -> NMP-E1 | B22: =精餾產銷!B21 -> 0 | C22: =精餾產銷!C21 -> 0 | D22: =精餾產銷!D21 -> 0 | E22: =精餾產銷!E21 -> 0 | F22: =精餾產銷!F21 -> 0 | G22: =精餾產銷!G21 -> 0 | H22: =精餾產銷!H21 -> 0 | ... AE22: =精餾產銷!AE21 -> 0 | AF22: =+IF(SUM(G22,H22:O22,R22,U22,X22,AA22)=0,0,1) -> 0 | AH22: =精餾產銷!AH21 -> 0 | AI22: =IF(AH22=0,0,AH22/C22) -> 0 | AJ22: =IF(AH22=0,0,AH22/((H22+J22+L22+N22)/4)) -> 0
A23: =精餾產銷!A22 -> CPNE3(T) | B23: =精餾產銷!B22 -> TK683.TK694&勝一 | C23: =精餾產銷!C22 -> 320 | D23: =精餾產銷!D22 -> 1.9 | E23: =精餾產銷!E22 -> 0 | F23: =精餾產銷!F22 -> 20 | G23: =精餾產銷!G22 -> 0 | H23: =精餾產銷!H22 -> 15 | ... AE23: =精餾產銷!AE22 -> 461 | AF23: =+IF(SUM(G23,H23:O23,R23,U23,X23,AA23)=0,0,1) -> 1 | AH23: =精餾產銷!AH22 -> 40 | AI23: =IF(AH23=0,0,AH23/C23) -> 0.125 | AJ23: =IF(AH23=0,0,AH23/((H23+J23+L23+N23)/4)) -> 0.1871345
A24: =精餾產銷!A23 -> CPNE3 | B24: =精餾產銷!B23 -> TK661&TK662&TK664&TK667&TK668 &[勝一(CPNE3(OEM)] | C24: =精餾產銷!C23 -> 285 | D24: =精餾產銷!D23 -> 109 | E24: =精餾產銷!E23 -> 0 | F24: =精餾產銷!F23 -> 0 | G24: =精餾產銷!G23 -> 109 | H24: =精餾產銷!H23 -> 30 | ... AE24: =精餾產銷!AE23 -> 218.5 | AF24: =+IF(SUM(G24,H24:O24,R24,U24,X24,AA24)=0,0,1) -> 1
A25: =精餾產銷!A24 -> CPNE3-R | B25: =精餾產銷!B24 -> TK601 | C25: =精餾產銷!C24 -> 225.625 | D25: =精餾產銷!D24 -> 222 | E25: =精餾產銷!E24 -> 0 | F25: =精餾產銷!F24 -> 0 | G25: =精餾產銷!G24 -> 222 | H25: =精餾產銷!H24 -> 0 | ... AE25: =精餾產銷!AE24 -> 177 | AF25: =+IF(SUM(G25,H25:O25,R25,U25,X25,AA25)=0,0,1) -> 1 | AH25: =精餾產銷!AH24 -> 0 | AI25: =IF(AH25=0,0,AH25/C25) -> 0 | AJ25: =IF(AH25=0,0,AH25/((H25+J25+L25+N25)/4)) -> 0
A26: =精餾產銷!A25 -> 2SEP05(E2) | B26: =精餾產銷!B25 -> 0 | C26: =精餾產銷!C25 -> 57 | D26: =精餾產銷!D25 -> 0 | E26: =精餾產銷!E25 -> 0 | F26: =精餾產銷!F25 -> 0 | G26: =精餾產銷!G25 -> 0 | H26: =精餾產銷!H25 -> 0 | ... AE26: =精餾產銷!AE25 -> 0 | AF26: =+IF(SUM(G26,H26:O26,R26,U26,X26,AA26)=0,0,1) -> 0 | AH26: =精餾產銷!AH25 -> 0 | AI26: =IF(AH26=0,0,AH26/C26) -> 0 | AJ26: =IF(AH26=0,0,AH26/((H26+J26+L26+N26)/4)) -> 0
A27: =精餾產銷!A26 -> 2DPM-1 | B27: =精餾產銷!B26 -> 0 | C27: =精餾產銷!C26 -> 0 | D27: =精餾產銷!D26 -> 0 | E27: =精餾產銷!E26 -> 0 | F27: =精餾產銷!F26 -> 0 | G27: =精餾產銷!G26 -> 0 | H27: =精餾產銷!H26 -> 0 | ... AE27: =精餾產銷!AE26 -> 0 | AF27: =+IF(SUM(G27,H27:O27,R27,U27,X27,AA27)=0,0,1) -> 0 | AH27: =精餾產銷!AH26 -> 0 | AI27: =IF(AH27=0,0,AH27/C27) -> 0 | AJ27: =IF(AH27=0,0,AH27/((H27+J27+L27+N27)/4)) -> 0
A28: =精餾產銷!A27 -> 委外加工 | B28: =精餾產銷!B27 -> 0 | C28: =精餾產銷!C27 -> 0 | D28: =精餾產銷!D27 -> 0 | E28: =精餾產銷!E27 -> 0 | F28: =精餾產銷!F27 -> 0 | G28: =精餾產銷!G27 -> 0 | H28: =精餾產銷!H27 -> 0 | ... AE28: =精餾產銷!AE27 -> 0 | AF28: =+IF(SUM(G28,H28:O28,R28,U28,X28,AA28)=0,0,1) -> 0 | AH28: =精餾產銷!AH27 -> 0 | AI28: =IF(AH28=0,0,AH28/C28) -> 0 | AJ28: =IF(AH28=0,0,AH28/((H28+J28+L28+N28)/4)) -> 0
A29: =精餾產銷!A28 -> EBRUPS | B29: =精餾產銷!B28 -> 0 | C29: =精餾產銷!C28 -> 75 | D29: =精餾產銷!D28 -> 0 | E29: =精餾產銷!E28 -> 0 | F29: =精餾產銷!F28 -> 0 | G29: =精餾產銷!G28 -> 0 | H29: =精餾產銷!H28 -> 0 | ... AE29: =精餾產銷!AE28 -> 0 | AF29: =+IF(SUM(G29,H29:O29,R29,U29,X29,AA29)=0,0,1) -> 0 | AH29: =精餾產銷!AH28 -> 0 | AI29: =IF(AH29=0,0,AH29/C29) -> 0 | AJ29: =IF(AH29=0,0,AH29/((H29+J29+L29+N29)/4)) -> 0
A30: =精餾產銷!A29 -> NMP-3 | B30: =精餾產銷!B29 -> 包材.TK611 | C30: =精餾產銷!C29 -> 23 | D30: =精餾產銷!D29 -> 5 | E30: =精餾產銷!E29 -> 0 | F30: =精餾產銷!F29 -> 0 | G30: =精餾產銷!G29 -> 5 | H30: =精餾產銷!H29 -> 0 | ... AE30: =精餾產銷!AE29 -> 5 | AF30: =+IF(SUM(G30,H30:O30,R30,U30,X30,AA30)=0,0,1) -> 1 | AH30: =精餾產銷!AH29 -> 0 | AI30: =IF(AH30=0,0,AH30/C30) -> 0 | AJ30: =IF(AH30=0,0,AH30/((H30+J30+L30+N30)/4)) -> 0
A31: =精餾產銷!A30 -> 外購 | B31: =精餾產銷!B30 -> 0 | C31: =精餾產銷!C30 -> 0 | D31: =精餾產銷!D30 -> 0 | E31: =精餾產銷!E30 -> 0 | F31: =精餾產銷!F30 -> 0 | G31: =精餾產銷!G30 -> 0 | H31: =精餾產銷!H30 -> 0 | ... AE31: =精餾產銷!AE30 -> 0 | AF31: =+IF(SUM(G31,H31:O31,R31,U31,X31,AA31)=0,0,1) -> 0 | AH31: =精餾產銷!AH30 -> 0 | AI31: =IF(AH31=0,0,AH31/C31) -> 0 | AJ31: =IF(AH31=0,0,AH31/((H31+J31+L31+N31)/4)) -> 0
A32: =精餾產銷!A31 -> 2IPA | B32: =精餾產銷!B31 -> 0 | C32: =精餾產銷!C31 -> 0 | D32: =精餾產銷!D31 -> 0 | E32: =精餾產銷!E31 -> 0 | F32: =精餾產銷!F31 -> 0 | G32: =精餾產銷!G31 -> 0 | H32: =精餾產銷!H31 -> 0 | ... AE32: =精餾產銷!AE31 -> 0 | AF32: =+IF(SUM(G32,H32:O32,R32,U32,X32,AA32)=0,0,1) -> 0 | AH32: =精餾產銷!AH31 -> 0 | AI32: =IF(AH32=0,0,AH32/C32) -> 0 | AJ32: =IF(AH32=0,0,AH32/((H32+J32+L32+N32)/4)) -> 0
A33: =精餾產銷!A32 -> 2EG | B33: =精餾產銷!B32 -> 0 | C33: =精餾產銷!C32 -> 249 | D33: =精餾產銷!D32 -> 0 | E33: =精餾產銷!E32 -> 0 | F33: =精餾產銷!F32 -> 0 | G33: =精餾產銷!G32 -> 0 | H33: =精餾產銷!H32 -> 0 | ... AE33: =精餾產銷!AE32 -> 0 | AF33: =+IF(SUM(G33,H33:O33,R33,U33,X33,AA33)=0,0,1) -> 1 | AH33: =精餾產銷!AH32 -> 0 | AI33: =IF(AH33=0,0,AH33/C33) -> 0 | AJ33: =IF(AH33=0,0,AH33/((H33+J33+L33+N33)/4)) -> 0
A34: =精餾產銷!A33 -> 2CPN | B34: =精餾產銷!B33 -> 0 | C34: =精餾產銷!C33 -> 0 | D34: =精餾產銷!D33 -> 0 | E34: =精餾產銷!E33 -> 0 | F34: =精餾產銷!F33 -> 0 | G34: =精餾產銷!G33 -> 0 | H34: =精餾產銷!H33 -> 0 | ... AE34: =精餾產銷!AE33 -> 0 | AF34: =+IF(SUM(G34,H34:O34,R34,U34,X34,AA34)=0,0,1) -> 0 | AH34: =精餾產銷!AH33 -> 0 | AI34: =IF(AH34=0,0,AH34/C34) -> 0 | AJ34: =IF(AH34=0,0,AH34/((H34+J34+L34+N34)/4)) -> 0
A35: =精餾產銷!A34 -> CPNE3-R(一次餾) | B35: =精餾產銷!B34 -> 0 | C35: =精餾產銷!C34 -> 0 | D35: =精餾產銷!D34 -> 0 | E35: =精餾產銷!E34 -> 0 | F35: =精餾產銷!F34 -> 0 | G35: =精餾產銷!G34 -> 0 | H35: =精餾產銷!H34 -> 0 | ... AE35: =精餾產銷!AE34 -> 0 | AF35: =+IF(SUM(G35,H35:O35,R35,U35,X35,AA35)=0,0,1) -> 0 | AH35: =精餾產銷!AH34 -> 0 | AI35: =IF(AH35=0,0,AH35/C35) -> 0 | AJ35: =IF(AH35=0,0,AH35/((H35+J35+L35+N35)/4)) -> 0
A36: =精餾產銷!A35 -> 0 | B36: =精餾產銷!B35 -> 0 | C36: =精餾產銷!C35 -> 0 | D36: =精餾產銷!D35 -> 0 | E36: =精餾產銷!E35 -> 0 | F36: =精餾產銷!F35 -> 0 | G36: =精餾產銷!G35 -> 0 | H36: =精餾產銷!H35 -> 0 | ... AE36: =精餾產銷!AE35 -> 0 | AF36: =+IF(SUM(G36,H36:O36,R36,U36,X36,AA36)=0,0,1) -> 0 | AH36: =精餾產銷!AH35 -> 0 | AI36: =IF(AH36=0,0,AH36/C36) -> 0 | AJ36: =IF(AH36=0,0,AH36/((H36+J36+L36+N36)/4)) -> 0
... A43: =精餾產銷!A42 -> 0 | B43: =精餾產銷!B42 -> 0 | C43: =精餾產銷!C42 -> 0 | D43: =精餾產銷!D42 -> 0 | E43: =精餾產銷!E42 -> 0 | F43: =精餾產銷!F42 -> 0 | G43: =精餾產銷!G42 -> 0 | H43: =精餾產銷!H42 -> 0 | ... AE43: =精餾產銷!AE42 -> 0 | AF43: =+IF(SUM(G43,H43:O43,R43,U43,X43,AA43)=0,0,1) -> 0 | AH43: =精餾產銷!AH42 -> 0 | AI43: =IF(AH43=0,0,AH43/C43) -> 0 | AJ43: =IF(AH43=0,0,AH43/((H43+J43+L43+N43)/4)) -> 0
G44: =IF(+D44+E44-F44<=0,0,+D44+E44-F44) -> 0 | P44: =+IF(Q44<>0,"S02",0) -> 0 | S44: =+IF(T44<>0,"S02",0) -> 0 | V44: =+IF(W44<>0,"S02",0) -> 0 | Y44: =+IF(Z44<>0,"S02",0) -> 0 | AB44: =+G44-SUM(H44:I44)+SUM(R44) -> 0 | AC44: =+AB44-SUM(J44:K44)+SUM(U44) -> 0 | AD44: =+AC44-SUM(L44:M44)+SUM(X44) -> 0 | AE44: =+AD44-SUM(N44:O44)+SUM(AA44) -> 0 | AF44: =+IF(SUM(G44,H44:O44,R44,U44,X44,AA44)=0,0,1) -> 0 | AH44: =精餾產銷!AH43 -> 0 | AI44: =IF(AH44=0,0,AH44/C44) -> 0 | AJ44: =IF(AH44=0,0,AH44/((H44+J44+L44+N44)/4)) -> 0
A45: =初餾產銷!A5 -> EBR-P1 | B45: =初餾產銷!B5 -> TK631&TK699 | C45: =初餾產銷!C5 -> 685 | D45: =初餾產銷!D5 -> 213.9 | E45: =初餾產銷!E5 -> 0 | F45: =初餾產銷!F5 -> 2 | G45: =初餾產銷!G5 -> 211.9 | H45: =初餾產銷!H5 -> 306 | I45: =初餾產銷!J5 -> 0 | J45: =初餾產銷!K5 -> 1550 | K45: =初餾產銷!M5 -> 0 | L45: =初餾產銷!N5 -> 1550 | M45: =初餾產銷!P5 -> 0 | N45: =初餾產銷!Q5 -> 1550 | O45: =初餾產銷!S5 -> 0 | P45: =初餾產銷!T5 -> R01 | Q45: =初餾產銷!U5 -> 24~31 | R45: =初餾產銷!V5 -> 350 | S45: =初餾產銷!W5 -> R02 | T45: =初餾產銷!X5 -> 1~31 | U45: =初餾產銷!Y5 -> 1500 | V45: =初餾產銷!Z5 -> R02 | ... AE45: =初餾產銷!AI5 -> 105.9 | AF45: =+IF(SUM(G45,H45:O45,R45,U45,X45,AA45)=0,0,1) -> 1 | AI45: =IF(AH45=0,0,AH45/C45) -> 0 | AJ45: =IF(AH45=0,0,AH45/((H45+J45+L45+N45)/4)) -> 0
A46: =初餾產銷!A6 -> CPN-P1 | B46: =初餾產銷!B6 -> TK634.TK653 | C46: =初餾產銷!C6 -> 450 | D46: =初餾產銷!D6 -> 187 | E46: =初餾產銷!E6 -> 511 | F46: =初餾產銷!F6 -> 0 | G46: =初餾產銷!G6 -> 698 | H46: =初餾產銷!H6 -> 0 | I46: =初餾產銷!J6 -> 0 | J46: =初餾產銷!K6 -> 0 | K46: =初餾產銷!M6 -> 763 | L46: =初餾產銷!N6 -> 0 | M46: =初餾產銷!P6 -> 861 | N46: =初餾產銷!Q6 -> 0 | O46: =初餾產銷!S6 -> 861 | P46: =初餾產銷!T6 -> R02 | Q46: =初餾產銷!U6 -> 24~31 | R46: =初餾產銷!V6 -> 160 | S46: =初餾產銷!W6 -> R01 | T46: =初餾產銷!X6 -> 1~31 | U46: =初餾產銷!Y6 -> 350 | V46: =初餾產銷!Z6 -> R01 | ... AE46: =初餾產銷!AI6 -> 3 | AF46: =+IF(SUM(G46,H46:O46,R46,U46,X46,AA46)=0,0,1) -> 1 | AI46: =IF(AH46=0,0,AH46/C46) -> 0 | AJ46: =IF(AH46=0,0,AH46/((H46+J46+L46+N46)/4)) -> 0
...

Sheet 精餾產銷
A1: 產銷計劃表(精餾)
A2: 單位：MT | AE2: =+"日期："&TEXT($G$3,"YYYY/MM/DD") -> 日期：2026/08/24
A3: 成品品名 | B3: 存放位置 (隱藏) | C3: 儲槽 容量 (MT) | D3: 資材 | E3: 製2 | F3: 桶底 | G3: 46258 | H3: =TEXT(+G3,"MM/DD")&"~"&TEXT(DATE(YEAR(G3),MONTH(G3)+1,1)-1,"MM/DD") -> 08/24~08/31 | J3: =+EOMONTH(G3,1) -> 46295 | L3: =+EOMONTH(J3,1) -> 46326 | N3: =+EOMONTH(L3,1) -> 46356 | P3: 生產量 | AB3: 庫存 | AG3: 安全庫存量
D4: 庫存 | E4: 庫存 | H4: 銷售 | I4: 耗用 | J4: 銷售 | K4: 耗用 | L4: 銷售 | M4: 耗用 | N4: 銷售 | O4: 耗用 | P4: =+IF(P3=0,0,+TEXT(LEFT($H$3,5),"DD")&"~"&TEXT(RIGHT($H$3,5),"D")) -> 24~31 | R4: 數量 | S4: =MONTH(J3)&"月" -> 9月 | U4: 數量 | V4: =+MONTH(L3)&"月" -> 10月 | X4: 數量 | Y4: =+MONTH(N3)&"月" -> 11月 | AA4: 數量 | AB4: =+TEXT(RIGHT(H3,5),"M/DD") -> 8/31 | AC4: =$J$3 -> 46295 | AD4: =$L$3 -> 46326 | AE4: =$N$3 -> 46356 | AG4: 最高 | AH4: 最低
A5: IPAUPS | B5: TK624.TK672.E68.小包 | C5: =385+50+16+4 -> 455 | D5: =36+17.5+9.5+37.341 -> 100.341 | F5: 25 | G5: =IF(+D5+E5-F5<=0,0,+D5+E5-F5) -> 75.341 | P5: =+IF(R5<>0,"S01",0) -> 0 | S5: =+IF(U5<>0,"S01",0) -> 0 | V5: =+IF(X5<>0,"S01",0) -> 0 | Y5: =+IF(AA5<>0,"S01",0) -> 0 | AB5: =+G5 -> 75.341 | AC5: =AB5-SUM(J5:K5)+SUM(U5) -> 75.341 | AD5: =AC5-SUM(L5:M5)+SUM(X5) -> 75.341 | AE5: =AD5-SUM(N5:O5)+SUM(AA5:AA5) -> 75.341 | AF5: =+IF(SUM(G2,H2:O2,Q5,S5,V5,Z5,+G5)>0,1,0) -> 1 | AH5: 150 | AK5: =+IF(SUM(G5,H5:O5,R5,U5,X5,AA5,AB5:AE5)<>0,1,0) -> 1
G6: =IF(+D6+E6-F6<=0,0,+D6+E6-F6) -> 0 | P6: =+IF(R6<>0,"S03",0) -> 0 | S6: =+IF(U6<>0,"S02",0) -> 0 | Y6: =+IF(AA6<>0,"S02",0) -> 0 | AF6: =+IF(SUM(G6,H6:O6,Q6,S6,V6,Z6)>0,1,0) -> 0 | AK6: =+IF(SUM(G6,H6:O6,R6,U6,X6,AA6,AB6:AE6)<>0,1,0) -> 0
A7: IPAUPS | G7: =IF(+D7+E7-F7<=0,0,+D7+E7-F7) -> 0 | P7: =+IF(R7<>0,"S03",0) -> 0 | AF7: =+IF(SUM(G7,H7:O7,Q7,S7,V7,Z7)>0,1,0) -> 0 | AK7: =+IF(SUM(G7,H7:O7,R7,U7,X7,AA7,AB7:AE7)<>0,1,0) -> 0
A8: IPAUPS(崙尾區日本料) | G8: =IF(+D8+E8-F8<=0,0,+D8+E8-F8) -> 0 | I8: 0 | K8: 10 | M8: 30 | O8: 30 | P8: =+IF(R8<>0,"S05",0) -> S05 | Q8: 26~31 | R8: =20*5 -> 100 | S8: S05 | T8: 1~30 | U8: =20*25 -> 500 | V8: S05 | W8: 1~31 | X8: =20*25 -> 500 | Y8: S05 | Z8: 1~31 | AA8: =20*25 -> 500 | AF8: =+IF(SUM(G5,H5:O5,Q8,S8,V8,Z8)>0,1,0) -> 1 | AK8: =+IF(SUM(G8,H8:O8,R8,U8,X8,AA8,AB8:AE8)<>0,1,0)+1 -> 2
A9: IPAUPS(崙尾區LG) | D9: =27.8+36.5+36+0.9 -> 101.2 | G9: =IF(+D9+E9-F9<=0,0,+D9+E9-F9) -> 101.2 | H9: 266 | I9: 5 | J9: =900+100 -> 1000 | K9: 40 | L9: =900+200 -> 1100 | M9: 30 | N9: =900+200 -> 1100 | O9: 30 | P9: S04 | Q9: 24~31 | R9: =30*7 -> 210 | S9: S04 | T9: 1~30 | U9: =30*30 -> 900 | V9: S04 | W9: 1~31 | X9: =30*30 -> 900 | Y9: S04 | Z9: 1~31 | AA9: =30*30 -> 900 | AB9: =+G9-SUM(H6:I9)+SUM(R6:R9) -> 140.2 | AC9: =+AB9-SUM(J6:K9)+SUM(U6:U9) -> 490.2 | AD9: =+AC9-SUM(L6:M9)+SUM(X6:X9) -> 730.2 | AE9: =+AD9-SUM(N6:O9)+SUM(AA6:AA9) -> 970.2 | AF9: =+IF(SUM(G5,H5:O5,Q9,S9,V9,Z9)>0,1,0) -> 1 | AK9: =+IF(SUM(G9,H9:O9,R9,U9,X9,AA9,AB9:AE9)<>0,1,0)+1 -> 2
A10: IPAHQ | B10: TK-681&TK-682 | C10: 156 | D10: =45.9+45.6 -> 91.5 | G10: =IF(+D10+E10-F10<=0,0,+D10+E10-F10) -> 91.5 | H10: 140 | I10: 22 | J10: 600 | K10: 85 | L10: 600 | M10: 85 | N10: 600 | O10: 85 | P10: =+IF(R10<>0,"S03",0) -> S03 | Q10: 24~31 | R10: 240 | S10: S03 | T10: 1~30 | U10: 960 | V10: =+IF(X10<>0,"S03",0) -> S03 | W10: 1~31 | X10: 990 | Y10: =+IF(AA10<>0,"S03",0) -> S03 | Z10: 1~30 | AA10: 960 | AB10: =+G10-SUM(H10:I10)+SUM(R10) -> 169.5 | AC10: =+AB10-SUM(J10:K10)+SUM(U10) -> 444.5 | AD10: =+AC10-SUM(L10:M10)+SUM(X10) -> 749.5 | AE10: =+AD10-SUM(N10:O10)+SUM(AA10) -> 1024.5 | AF10: =+IF(SUM(G10,H10:O10,Q10,S10,V10,Z10)>0,1,0) -> 1 | AH10: 40 | AK10: =+IF(SUM(G10,H10:O10,R10,U10,X10,AA10,AB10:AE10)<>0,1,0) -> 1
A11: EGUPS | B11: TK623.E40.E48.E56.E59.E60.E66.E67(E21 外部鏽蝕處理中).TK692.TK689 | C11: =260+277 -> 537 | D11: =3+11.5+(36-29.6) -> 20.9 | E11: 0 | F11: 14 | G11: =IF(+D11+E11-F11<=0,0,+D11+E11-F11) -> 6.9 | H11: 5 | I11: =+SUMIF(秏料!$B$3:$B$133,$A11,秏料!$F$3:$F$133) -> 52.436 | J11: 20 | K11: =+SUMIF(秏料!$B$3:$B$133,$A11,秏料!$H$3:$H$133) -> 291.005 | L11: 20 | M11: =+SUMIF(秏料!$B$3:$B$133,$A11,秏料!$J$3:$J$133) -> 291.005 | N11: 20 | O11: =+SUMIF(秏料!$B$3:$B$133,$A11,秏料!$L$3:$L$133) -> 291.005 | P11: S02 | Q11: 24~31 | R11: 200 | S11: S02 | T11: 1~5 | U11: =140 -> 140 | Z11: 純七 | AA11: 675 | AB11: =+G11:G12-SUM(H11:I12)+SUM(R11:R12) -> 149.464 | AC11: =+AB11-SUM(J11:K11)+SUM(U11:U12) -> 748.459 | AD11: =+AC11-SUM(L11:M11)+SUM(X11:X12) -> 437.454 | AE11: =+AD11-SUM(N11:O11)+SUM(AA11:AA12) -> 801.449 | AF11: =+IF(SUM(G11,H11:O11,Q11,S11,V11,Z11)>0,1,0) -> 1 | AH11: 24.94 | AK11: =+IF(SUM(G11,H11:O11,R11,U11,X11,AA11,AB11:AE11)<>0,1,0) -> 1
A12: EGUPS(勝一S07) | G12: =IF(+D12+E12-F12<=0,0,+D12+E12-F12) -> 0 | T12: 純七 | U12: 770 | AF12: 1 | AK12: =+IF(SUM(G12,H12:O12,R12,U12,X12,AA12,AB12:AE12)<>0,1,0) -> 1
A13: EGUPS(EG-C) | B13: TK689 | D13: =29.6+26.26 -> 55.86 | G13: =IF(+E13-F13<=0,0,+E13-F13) -> 0 | I13: =+SUMIF(秏料!$B$3:$B$133,$A13,秏料!$F$3:$F$133) -> 0 | K13: =+SUMIF(秏料!$B$3:$B$133,$A13,秏料!$H$3:$H$133) -> 0 | M13: =+SUMIF(秏料!$B$3:$B$133,$A13,秏料!$J$3:$J$133) -> 0 | O13: =+SUMIF(秏料!$B$3:$B$133,$A13,秏料!$L$3:$L$133) -> 0 | S13: =+IF(U13<>0,"S01",0) -> 0 | V13: =+IF(X13<>0,"S01",0) -> 0 | AB13: =+G13+R13-SUM(H13:I13) -> 0 | AC13: =+AB13+U13-SUM(J13:K13) -> 0 | AD13: =+AC13-SUM(L13:M13)+SUM(X13) -> 0 | AE13: =+AD13+AA13-SUM(N13:O13) -> 0 | AF13: 1 | AK13: =+IF(SUM(G13,H13:O13,R13,U13,X13,AA13,AB13:AE13)<>0,1,0) -> 0
A14: CPNE4(含浸) | B14: TK677&TK680 | C14: 72 | D14: =0 -> 0 | F14: 0 | G14: =IF(+D14+E14-F14<=0,0,+D14+E14-F14) -> 0 | I14: =+SUMIF(秏料!$B$3:$B$133,$A14,秏料!$F$3:$F$133) -> 0 | P14: =+IF(R14<>0,"S02",0) -> 0 | S14: =+IF(U14<>0,"S02",0) -> 0 | V14: =+IF(X14<>0,"S02",0) -> 0 | Y14: =+IF(AA14<>0,"S02",0) -> 0 | AB14: =+G14-SUM(H14:I14)+SUM(R14) -> 0 | AC14: =+AB14-SUM(J14:K14)+SUM(U14) -> 0 | AD14: =+AC14-SUM(L14:M14)+SUM(X14) -> 0 | AE14: =+AD14-SUM(N14:O14)+SUM(AA14) -> 0 | AF14: =+IF(SUM(G14,H14:O14,Q14,S14,V14,Z14)>0,1,0) -> 0 | AK14: =+IF(SUM(G14,H14:O14,R14,U14,X14,AA14,AB14:AE14)<>0,1,0) -> 0
A15: CPNE4R(含浸) | B15: TK694 | C15: 230 | D15: =0 -> 0 | F15: 1 | G15: =IF(+D15+E15-F15<=0,0,+D15+E15-F15) -> 0 | H15: 0 | J15: 0 | AB15: =+G15-SUM(H15:I15)+SUM(R15) -> 0 | AC15: =+AB15-SUM(J15:K15)+SUM(U15) -> 0 | AD15: =+AC15-SUM(L15:M15)+SUM(X15) -> 0 | AE15: =+AD15-SUM(N15:O15)+SUM(AA15) -> 0 | AF15: =+IF(SUM(G15,H15:O15,Q15,S15,V15,Z15)>0,1,0) -> 0 | AK15: =+IF(SUM(G15,H15:O15,R15,U15,X15,AA15,AB15:AE15)<>0,1,0) -> 0
A16: CPNE4 | B16: TK677&TK680&勝一 | C16: =25+45+240+45 -> 355 | D16: =2+0+(20) -> 22 | F16: 21 | G16: =IF(+D16+E16-F16<=0,0,+D16+E16-F16) -> 1 | H16: 130 | I16: =+SUMIF(秏料!$B$3:$B$133,$A16,秏料!$F$3:$F$133) -> 0 | J16: 300 | K16: =+SUMIF(秏料!$B$3:$B$133,$A16,秏料!$H$3:$H$133) -> 0 | L16: 300 | M16: =+SUMIF(秏料!$B$3:$B$133,$A16,秏料!$J$3:$J$133) -> 0 | N16: 300 | O16: =+SUMIF(秏料!$B$3:$B$133,$A16,秏料!$L$3:$L$133) -> 0 | P16: =+IF(R16<>0,"S01",0) -> S01 | Q16: 24~27 | R16: 110 | S16: S02 | T16: 11~21 | U16: 300 | V16: S02 | W16: 6~16 | X16: 320 | Y16: =+IF(AA16<>0,"S02",0) -> S02 | Z16: 1~10 | AA16: 290 | AB16: =+G16-SUM(H16:I16)+SUM(R16) -> -19 | AC16: =+AB16-SUM(J16:K16)+SUM(U16) -> -19 | AD16: =+AC16-SUM(L16:M16)+SUM(X16) -> 1 | AE16: =+AD16-SUM(N16:O16)+SUM(AA16) -> -9 | AF16: =+IF(SUM(G16,H16:O16,Q16,S16,V16,Z16)>0,1,0) -> 1 | AH16: 90 | AK16: =+IF(SUM(G16,H16:O16,R16,U16,X16,AA16,AB16:AE16)<>0,1,0) -> 1
A17: ACTUPS | B17: TK622.TK612.包材 | C17: =16+176 -> 192 | D17: =68+17.5+25.368 -> 110.868 | F17: =15+2 -> 17 | G17: =IF(+D17+E17-F17<=0,0,+D17+E17-F17) -> 93.868 | H17: 5 | J17: 50 | L17: 50 | N17: 50 | V17: =+IF(X17<>0,"S01",0) -> S01 | W17: 4~12 | X17: 210 | Y17: =+IF(AA17<>0,"S01",0) -> 0 | AB17: =+G17-SUM(H17:I17)+SUM(R17:R18) -> 88.868 | AC17: =+AB17-SUM(J17:K17)+SUM(U17:U18) -> 38.868 | AD17: =+AC17-SUM(L17:M17)+SUM(X17:X18) -> 198.868 | AE17: =+AD17-SUM(N17:O17)+SUM(AA17:AA18) -> 148.868 | AF17: =+IF(SUM(G17,H17:O17,Q17,S17,V17,Z17)>0,1,0) -> 1 | AH17: 35.2 | AK17: =+IF(SUM(G17,H17:O17,R17,U17,X17,AA17,AB17:AE17)<>0,1,0) -> 1
A18: 外購 | G18: =IF(+D18+E18-F18<=0,0,+D18+E18-F18) -> 0 | P18: =+IF(R18<>0,"外購",0) -> 0 | S18: =+IF(U18<>0,"外購",0) -> 0 | V18: =+IF(X18<>0,"外購",0) -> 0 | Y18: =+IF(AA18<>0,"外購",0) -> 0 | AF18: =+IF(SUM(G18,H18:O18,Q18,S18,V18,Z18)>0,1,0) -> 0 | AK18: =+IF(SUM(G18,H18:O18,R18,U18,X18,AA18,AB18:AE18)<>0,1,0) -> 0
A19: NMPUPS | B19: TK621.E58.E26.E31.包材 | C19: =225+0+18.5 -> 243.5 | D19: =144.5+0+0+4.4+0 -> 148.9 | E19: 10 | F19: 15 | G19: =IF(+D19+E19-F19<=0,0,+D19+E19-F19) -> 143.9 | H19: 0 | J19: 42 | L19: 30 | N19: 42 | S19: =+IF(U19<>0,"S02",0) -> 0 | V19: =+IF(X19<>0,"S02",0) -> 0 | Y19: =+IF(AA19<>0,"S02",0) -> 0 | AB19: =+G19-SUM(H19:I19)+SUM(R19:R20) -> 143.9 | AC19: =+AB19-SUM(J19:K19)+SUM(U19:U20) -> 101.9 | AD19: =+AC19-SUM(L19:M19)+SUM(X19:X20) -> 71.9 | AE19: =+AD19-SUM(N19:O19)+SUM(AA19:AA20) -> 29.9 | AF19: =+IF(SUM(G19,H19:O19,Q19,S19,V19,Z19)>0,1,0) -> 1 | AH19: 46.2 | AK19: =+IF(SUM(G19,H19:O19,R19,U19,X19,AA19,AB19:AE19)<>0,1,0) -> 1
A20: 外購 | G20: =IF(+D20+E20-F20<=0,0,+D20+E20-F20) -> 0 | P20: =+IF(R20<>0,"外購",0) -> 0 | S20: =+IF(U20<>0,"外購",0) -> 0 | V20: =+IF(X20<>0,"外購",0) -> 0 | Y20: =+IF(AA20<>0,"外購",0) -> 0 | AF20: =+IF(SUM(G20,H20:O20,Q20,S20,V20,Z20)>0,1,0) -> 0 | AK20: =+IF(SUM(G20,H20:O20,R20,U20,X20,AA20,AB20:AE20)<>0,1,0) -> 0
A21: NMP-E1 | G21: =IF(+D21+E21-F21<=0,0,+D21+E21-F21) -> 0 | H21: 0 | L21: 0 | N21: 0 | P21: =+IF(R21<>0,"S02",0) -> 0 | S21: =+IF(U21<>0,"S02",0) -> 0 | V21: =+IF(X21<>0,"S02",0) -> 0 | Y21: =+IF(AA21<>0,"S02",0) -> 0 | AB21: =+G21-SUM(H21:I21)+SUM(R21) -> 0 | AC21: =+AB21-SUM(J21:K21)+SUM(U21) -> 0 | AD21: =+AC21-SUM(L21:M21)+SUM(X21) -> 0 | AE21: =+AD21-SUM(N21:O21)+SUM(AA21) -> 0 | AF21: =+IF(SUM(G21,H21:O21,Q21,S21,V21,Z21)>0,1,0) -> 0 | AK21: =+IF(SUM(G21,H21:O21,R21,U21,X21,AA21,AB21:AE21)<>0,1,0) -> 0
A22: CPNE3(T) | B22: TK683.TK694&勝一 | C22: =95+225 -> 320 | D22: =1.9+0+(0) -> 1.9 | F22: 20 | G22: =IF(+D22+E22-F22<=0,0,+D22+E22-F22) -> 0 | H22: 15 | I22: =+SUMIF(秏料!$B$3:$B$133,$A22,秏料!$F$3:$F$133) -> 0 | J22: 280 | K22: =+SUMIF(秏料!$B$3:$B$133,$A22,秏料!$H$3:$H$133) -> 0 | L22: 280 | M22: =+SUMIF(秏料!$B$3:$B$133,$A22,秏料!$J$3:$J$133) -> 0 | N22: 280 | P22: =+IF(R22<>0,"S01",0) -> S01 | Q22: (1)24 (1)31 | R22: =18+18 -> 36 | S22: =+IF(U22<>0,"S01+S02",0) -> S01+S02 | T22: (2)22~27 (1)1~4 | U22: =30*6+30*4 -> 300 | V22: =+IF(X22<>0,"S01+S02",0) -> S01+S02 | W22: (2)1~5 (2)17~21 (2)26~31 | X22: =150+150+150 -> 450 | Y22: =+IF(AA22<>0,"S02+S01",0) -> S02+S01 | Z22: (2)11~16 (2)21~27 (1)24~30 | AA22: =180+180+170 -> 530 | AB22: =+G22-SUM(H22:I22)+SUM(R22) -> 21 | AC22: =+AB22-SUM(J22:K22)+SUM(U22) -> 41 | AD22: =+AC22-SUM(L22:M22)+SUM(X22) -> 211 | AE22: =+AD22-SUM(N22:O22)+SUM(AA22) -> 461 | AF22: =+IF(SUM(G22,H22:O22,Q22,S22,V22,Z22)>0,1,0) -> 1 | AH22: 40 | AK22: =+IF(SUM(G22,H22:O22,R22,U22,X22,AA22,AB22:AE22)<>0,1,0) -> 1
A23: CPNE3 | B23: TK661&TK662&TK664&TK667&TK668 &[勝一(CPNE3(OEM)] | C23: =65+65+65+45+45 -> 285 | D23: =38+19+1.6+5+12+3.9+(29.5) -> 109 | G23: =IF(+D23+E23-F23<=0,0,+D23+E23-F23) -> 109 | H23: 30 | I23: =+SUMIF(秏料!$B$3:$B$133,$A23,秏料!$F$3:$F$133) -> 40 | J23: 80 | K23: =+SUMIF(秏料!$B$3:$B$133,$A23,秏料!$H$3:$H$133) -> 330 | L23: 80 | M23: =+SUMIF(秏料!$B$3:$B$133,$A23,秏料!$J$3:$J$133) -> 495 | N23: 80 | O23: =+SUMIF(秏料!$B$3:$B$133,$A23,秏料!$L$3:$L$133) -> 583 | P23: S01 | Q23: (1)28~30 | R23: =(45*3) -> 135 | S23: =+IF(U23<>0,"S01",0) -> S01 | T23: (1)5~6 (1)15~20 (2)28~30 | U23: =190+210+165 -> 565 | V23: =+IF(X23<>0,"S01+S02",0) -> S01+S02 | W23: (1)8~13 (1)21~25 (2)22~25 | X23: =(45*13.5) -> 607.5 | Y23: =+IF(AA23<>0,"S02",0) -> S02 | Z23: (2)17~20 (2)28~30 (1)21~23 | AA23: =275+165+80 -> 520 | AB23: =+G23-SUM(H23:I23)+SUM(R23) -> 174 | AC23: =+AB23-SUM(J23:K23)+SUM(U23) -> 329 | AD23: =+AC23-SUM(L23:M23)+SUM(X23) -> 361.5 | AE23: =+AD23-SUM(N23:O23)+SUM(AA23) -> 218.5 | AF23: =+IF(SUM(G23,H23:O23,Q23,S23,V23,Z23)>0,1,0) -> 1 | AK23: 1
A24: CPNE3-R | B24: TK601 | C24: =250*0.95*0.95 -> 225.625 | D24: 222 | G24: =IF(+D24+E24-F24<=0,0,+D24+E24-F24) -> 222 | H24: 0 | I24: =+SUMIF(秏料!$B$3:$B$133,$A24,秏料!$F$3:$F$133) -> 153 | K24: =+SUMIF(秏料!$B$3:$B$133,$A24,秏料!$H$3:$H$133) -> 638 | M24: =+SUMIF(秏料!$B$3:$B$133,$A24,秏料!$J$3:$J$133) -> 686 | N24: 0 | O24: =+SUMIF(秏料!$B$3:$B$133,$A24,秏料!$L$3:$L$133) -> 588 | P24: =+IF(R24<>0,"S01+S02",0) -> 0 | S24: =+IF(U24<>0,"S01",0) -> S01 | T24: (1)7~14 (1)21~30 | U24: =270+(35*10) -> 620 | V24: =+IF(X24<>0,"S01",0) -> S01 | W24: (1)1~7 (1)14~20 (1)26~31 | X24: =(35*20) -> 700 | Y24: =+IF(AA24<>0,"S01",0) -> S01 | Z24: (1)1~20 | AA24: 700 | AB24: =+G24-SUM(H24:I24)+SUM(R24) -> 69 | AC24: =+AB24-SUM(J24:K24)+SUM(U24) -> 51 | AD24: =+AC24-SUM(L24:M24)+SUM(X24) -> 65 | AE24: =+AD24-SUM(N24:O24)+SUM(AA24) -> 177 | AF24: =+IF(SUM(G24,H24:O24,Q24,S24,V24,Z24)>0,1,0) -> 1 | AK24: =+IF(SUM(G24,H24:O24,R24,U24,X24,AA24,AB24:AE24)<>0,1,0) -> 1
A25: 2SEP05(E2) | C25: 57 | G25: =IF(+D25+E25-F25<=0,0,+D25+E25-F25) -> 0 | H25: 0 | J25: 0 | P25: =+IF(R25<>0,"S02",0) -> 0 | S25: =+IF(U25<>0,"S02",0) -> 0 | V25: =+IF(X25<>0,"S02",0) -> 0 | Y25: =+IF(AA25<>0,"S02",0) -> 0 | AB25: =+G25-SUM(H25:I25)+SUM(R25) -> 0 | AC25: =+AB25-SUM(J25:K25)+SUM(U25) -> 0 | AD25: =+AC25-SUM(L25:M25)+SUM(X25) -> 0 | AE25: =+AD25-SUM(N25:O25)+SUM(AA25) -> 0 | AF25: =+IF(SUM(G25,H25:O25,Q25,S25,V25,Z25)>0,1,0) -> 0 | AK25: =+IF(SUM(G25,H25:O25,R25,U25,X25,AA25,AB25:AE25)<>0,1,0) -> 0
A26: 2DPM-1 | G26: =IF(+D26+E26-F26<=0,0,+D26+E26-F26) -> 0 | P26: =+IF(R26<>0,"S02",0) -> 0 | S26: =+IF(U26<>0,"S02",0) -> 0 | V26: =+IF(X26<>0,"S02",0) -> 0 | Y26: =+IF(AA26<>0,"S02",0) -> 0 | AB26: =+G26-SUM(H26:I26)+SUM(R26:R27) -> 0 | AC26: =+AB26-SUM(J26:K26)+SUM(U26:U27) -> 0 | AD26: =+AC26-SUM(L26:M26)+SUM(X26:X27) -> 0 | AE26: =+AD26-SUM(N26:O26)+SUM(AA26:AA27) -> 0 | AF26: =+IF(SUM(G26,H26:O26,Q26,S26,V26,Z26)>0,1,0) -> 0 | AK26: =+IF(SUM(G26,H26:O26,R26,U26,X26,AA26,AB26:AE26)<>0,1,0) -> 0
A27: 委外加工 | G27: =IF(+D27+E27-F27<=0,0,+D27+E27-F27) -> 0 | AF27: =+IF(SUM(G27,H27:O27,Q27,S27,V27,Z27)>0,1,0) -> 0 | AK27: =+IF(SUM(G27,H27:O27,R27,U27,X27,AA27,AB27:AE27)<>0,1,0) -> 0
A28: EBRUPS | C28: 75 | G28: =IF(+D28+E28-F28<=0,0,+D28+E28-F28) -> 0 | P28: =+IF(R28<>0,"S02",0) -> 0 | S28: =+IF(U28<>0,"S02",0) -> 0 | V28: =+IF(X28<>0,"S02",0) -> 0 | Y28: =+IF(AA28<>0,"S02",0) -> 0 | AB28: =+G28-SUM(H28:I28)+SUM(R28) -> 0 | AC28: =+AB28-SUM(J28:K28)+SUM(U28) -> 0 | AD28: =+AC28-SUM(L28:M28)+SUM(X28) -> 0 | AE28: =+AD28-SUM(N28:O28)+SUM(AA28) -> 0 | AF28: =+IF(SUM(G28,H28:O28,Q28,S28,V28,Z28)>0,1,0) -> 0 | AK28: =+IF(SUM(G28,H28:O28,R28,U28,X28,AA28,AB28:AE28)<>0,1,0) -> 0
A29: NMP-3 | B29: 包材.TK611 | C29: 23 | D29: 5 | G29: =IF(+D29+E29-F29<=0,0,+D29+E29-F29) -> 5 | H29: 0 | J29: 0 | P29: =+IF(R29<>0,"S02",0) -> 0 | S29: =+IF(U29<>0,"S02",0) -> 0 | V29: =+IF(X29<>0,"S02",0) -> 0 | Y29: =+IF(AA29<>0,"S02",0) -> 0 | AB29: =+G29-SUM(H29:I29)+SUM(R29:R30) -> 5 | AC29: =+AB29-SUM(J29:K29)+SUM(U29:U30) -> 5 | AD29: =+AC29-SUM(L29:M29)+SUM(X29:X30) -> 5 | AE29: =+AD29-SUM(N29:O29)+SUM(AA29:AA30) -> 5 | AF29: 1 | AK29: =+IF(SUM(G29,H29:O29,R29,U29,X29,AA29,AB29:AE29)<>0,1,0) -> 1
A30: 外購 | R30: 0 | AK30: =+IF(SUM(G30,H30:O30,R30,U30,X30,AA30,AB30:AE30)<>0,1,0) -> 0
A31: 2IPA | G31: =IF(+D31+E31-F31<=0,0,+D31+E31-F31) -> 0 | P31: =+IF(R31<>0,"S01",0) -> 0 | S31: =+IF(U31<>0,"S01",0) -> 0 | V31: =+IF(X31<>0,"S01",0) -> 0 | Y31: =+IF(AA31<>0,"S01",0) -> 0 | AB31: =+G31-SUM(H31:I31)+SUM(R31) -> 0 | AC31: =+AB31-SUM(J31:K31)+SUM(U31) -> 0 | AD31: =+AC31-SUM(L31:M31)+SUM(X31) -> 0 | AE31: =+AD31-SUM(N31:O31)+SUM(AA31) -> 0 | AF31: =+IF(SUM(G31,H31:O31,Q31,S31,V31,Z31)>0,1,0) -> 0 | AK31: =+IF(SUM(G31,H31:O31,R31,U31,X31,AA31,AB31:AE31)<>0,1,0) -> 0
A32: 2EG | C32: 249 | G32: =IF(+D32+E32-F32<=0,0,+D32+E32-F32) -> 0 | I32: =+$R$32 -> 0 | K32: =$U$32 -> 35 | M32: =$X$32 -> 0 | O32: =$AA$32 -> 0 | S32: S02 | T32: 6~7 | U32: 35 | AB32: =+G32-SUM(H32:I32)+SUM(R32) -> 0 | AC32: =+AB32-SUM(J32:K32)+SUM(U32) -> 0 | AD32: =+AC32-SUM(L32:M32)+SUM(X32) -> 0 | AE32: =+AD32-SUM(N32:O32)+SUM(AA32) -> 0 | AF32: =+IF(SUM(G32,H32:O32,Q32,S32,V32,Z32)>0,1,0) -> 1 | AK32: =+IF(SUM(G32,H32:O32,R32,U32,X32,AA32,AB32:AE32)<>0,1,0) -> 1
A33: 2CPN | G33: =IF(+D33+E33-F33<=0,0,+D33+E33-F33) -> 0 | I33: =$R$33 -> 0 | K33: =$U$33 -> 0 | M33: =$X$33 -> 0 | O33: =$AA$33 -> 0 | P33: =+IF(R33<>0,"S02",0) -> 0 | S33: =+IF(U33<>0,"S02",0) -> 0 | V33: =+IF(X33<>0,"S02",0) -> 0 | Y33: =+IF(AA33<>0,"S02",0) -> 0 | AB33: =+G33-SUM(H33:I33)+SUM(R33) -> 0 | AC33: =+AB33-SUM(J33:K33)+SUM(U33) -> 0 | AD33: =+AC33-SUM(L33:M33)+SUM(X33) -> 0 | AE33: =+AD33-SUM(N33:O33)+SUM(AA33) -> 0 | AF33: =+IF(SUM(G33,H33:O33,Q33,S33,V33,Z33)>0,1,0) -> 0 | AK33: =+IF(SUM(G33,H33:O33,R33,U33,X33,AA33,AB33:AE33)<>0,1,0) -> 0
A34: CPNE3-R(一次餾) | G34: =IF(+D34+E34-F34<=0,0,+D34+E34-F34) -> 0 | P34: =+IF(R34<>0,"S02",0) -> 0 | S34: =+IF(U34<>0,"S02",0) -> 0 | V34: =+IF(X34<>0,"S02",0) -> 0 | Y34: =+IF(AA34<>0,"S02",0) -> 0 | AB34: =+G34-SUM(H34:I34)+SUM(R34) -> 0 | AC34: =+AB34-SUM(J34:K34)+SUM(U34) -> 0 | AD34: =+AC34-SUM(L34:M34)+SUM(X34) -> 0 | AE34: =+AD34-SUM(N34:O34)+SUM(AA34) -> 0 | AF34: =+IF(SUM(G34,H34:O34,Q34,S34,V34,Z34)>0,1,0) -> 0 | AK34: =+IF(SUM(G34,H34:O34,R34,U34,X34,AA34,AB34:AE34)<>0,1,0) -> 0
G35: =IF(+D35+E35-F35<=0,0,+D35+E35-F35) -> 0 | P35: =+IF(R35<>0,"S02",0) -> 0 | S35: =+IF(U35<>0,"S02",0) -> 0 | V35: =+IF(X35<>0,"S02",0) -> 0 | Y35: =+IF(AA35<>0,"S02",0) -> 0 | AB35: =+G35-SUM(H35:I35)+SUM(R35) -> 0 | AC35: =+AB35-SUM(J35:K35)+SUM(U35) -> 0 | AD35: =+AC35-SUM(L35:M35)+SUM(X35) -> 0 | AE35: =+AD35-SUM(N35:O35)+SUM(AA35) -> 0 | AF35: =+IF(SUM(G35,H35:O35,Q35,S35,V35,Z35)>0,1,0) -> 0 | AK35: =+IF(SUM(G35,H35:O35,R35,U35,X35,AA35,AB35:AE35)<>0,1,0) -> 0
G36: =IF(+D36+E36-F36<=0,0,+D36+E36-F36) -> 0 | P36: =+IF(R36<>0,"S02",0) -> 0 | S36: =+IF(U36<>0,"S02",0) -> 0 | V36: =+IF(X36<>0,"S02",0) -> 0 | Y36: =+IF(AA36<>0,"S02",0) -> 0 | AB36: =+G36-SUM(H36:I36)+SUM(R36) -> 0 | AC36: =+AB36-SUM(J36:K36)+SUM(U36) -> 0 | AD36: =+AC36-SUM(L36:M36)+SUM(X36) -> 0 | AE36: =+AD36-SUM(N36:O36)+SUM(AA36) -> 0 | AF36: =+IF(SUM(G36,H36:O36,Q36,S36,V36,Z36)>0,1,0) -> 0 | AK36: =+IF(SUM(G36,H36:O36,R36,U36,X36,AA36,AB36:AE36)<>0,1,0) -> 0
G37: =IF(+D37+E37-F37<=0,0,+D37+E37-F37) -> 0 | P37: =+IF(R37<>0,"S02",0) -> 0 | S37: =+IF(U37<>0,"S02",0) -> 0 | V37: =+IF(X37<>0,"S02",0) -> 0 | Y37: =+IF(AA37<>0,"S02",0) -> 0 | AB37: =+G37-SUM(H37:I37)+SUM(R37) -> 0 | AC37: =+AB37-SUM(J37:K37)+SUM(U37) -> 0 | AD37: =+AC37-SUM(L37:M37)+SUM(X37) -> 0 | AE37: =+AD37-SUM(N37:O37)+SUM(AA37) -> 0 | AF37: =+IF(SUM(G37,H37:O37,Q37,S37,V37,Z37)>0,1,0) -> 0 | AK37: =+IF(SUM(G37,H37:O37,R37,U37,X37,AA37,AB37:AE37)<>0,1,0) -> 0
G38: =IF(+D38+E38-F38<=0,0,+D38+E38-F38) -> 0 | P38: =+IF(R38<>0,"S02",0) -> 0 | S38: =+IF(U38<>0,"S02",0) -> 0 | V38: =+IF(X38<>0,"S02",0) -> 0 | Y38: =+IF(AA38<>0,"S02",0) -> 0 | AB38: =+G38-SUM(H38:I38)+SUM(R38) -> 0 | AC38: =+AB38-SUM(J38:K38)+SUM(U38) -> 0 | AD38: =+AC38-SUM(L38:M38)+SUM(X38) -> 0 | AE38: =+AD38-SUM(N38:O38)+SUM(AA38) -> 0 | AF38: =+IF(SUM(G38,H38:O38,Q38,S38,V38,Z38)>0,1,0) -> 0 | AK38: =+IF(SUM(G38,H38:O38,R38,U38,X38,AA38,AB38:AE38)<>0,1,0) -> 0
G39: =IF(+D39+E39-F39<=0,0,+D39+E39-F39) -> 0 | P39: =+IF(R39<>0,"S02",0) -> 0 | S39: =+IF(U39<>0,"S02",0) -> 0 | V39: =+IF(X39<>0,"S02",0) -> 0 | Y39: =+IF(AA39<>0,"S02",0) -> 0 | AB39: =+G39-SUM(H39:I39)+SUM(R39) -> 0 | AC39: =+AB39-SUM(J39:K39)+SUM(U39) -> 0 | AD39: =+AC39-SUM(L39:M39)+SUM(X39) -> 0 | AE39: =+AD39-SUM(N39:O39)+SUM(AA39) -> 0 | AF39: =+IF(SUM(G39,H39:O39,Q39,S39,V39,Z39)>0,1,0) -> 0 | AK39: =+IF(SUM(G39,H39:O39,R39,U39,X39,AA39,AB39:AE39)<>0,1,0) -> 0
G40: =IF(+D40+E40-F40<=0,0,+D40+E40-F40) -> 0 | P40: =+IF(R40<>0,"S02",0) -> 0 | S40: =+IF(U40<>0,"S02",0) -> 0 | V40: =+IF(X40<>0,"S02",0) -> 0 | Y40: =+IF(AA40<>0,"S02",0) -> 0 | AB40: =+G40-SUM(H40:I40)+SUM(R40) -> 0 | AC40: =+AB40-SUM(J40:K40)+SUM(U40) -> 0 | AD40: =+AC40-SUM(L40:M40)+SUM(X40) -> 0 | AE40: =+AD40-SUM(N40:O40)+SUM(AA40) -> 0 | AF40: =+IF(SUM(G40,H40:O40,Q40,S40,V40,Z40)>0,1,0) -> 0 | AK40: =+IF(SUM(G40,H40:O40,R40,U40,X40,AA40,AB40:AE40)<>0,1,0) -> 0
...

Sheet 初餾產銷
A1: 產銷計劃表(初餾)
A2: 單位：MT | AI2: =+"日期："&TEXT($G$3,"YYYY/MM/DD") -> 日期：2026/08/24
A3: =精餾產銷!A3 -> 成品品名 | B3: =精餾產銷!B3 -> 存放位置 (隱藏) | C3: =精餾產銷!C3 -> 儲槽 容量 (MT) | D3: =精餾產銷!D3 -> 資材 | E3: =精餾產銷!E3 -> 製2 | F3: =精餾產銷!F3 -> 桶底 | G3: =精餾產銷!G3 -> 46258 | H3: =精餾產銷!H3 -> 08/24~08/31 | K3: =精餾產銷!J3 -> 46295 | N3: =精餾產銷!L3 -> 46326 | Q3: =精餾產銷!N3 -> 46356 | T3: =精餾產銷!P3 -> 生產量 | AF3: =精餾產銷!AB3 -> 庫存 | AL3: 安全庫存量
D4: =精餾產銷!D4 -> 庫存 | E4: =精餾產銷!E4 -> 庫存 | H4: =精餾產銷!H4 -> 銷售 | I4: 代工 入庫 | J4: =精餾產銷!I4 -> 耗用 | K4: =精餾產銷!J4 -> 銷售 | L4: 代工 入庫 | M4: =精餾產銷!K4 -> 耗用 | N4: =精餾產銷!L4 -> 銷售 | O4: 代工 入庫 | P4: =精餾產銷!M4 -> 耗用 | Q4: =精餾產銷!N4 -> 銷售 | R4: 代工 入庫 | S4: =精餾產銷!O4 -> 耗用 | T4: =精餾產銷!P4 -> 24~31 | V4: =精餾產銷!R4 -> 數量 | W4: =精餾產銷!S4 -> 9月 | Y4: =精餾產銷!U4 -> 數量 | Z4: =精餾產銷!V4 -> 10月 | AB4: =精餾產銷!X4 -> 數量 | AC4: =精餾產銷!Y4 -> 11月 | AE4: =精餾產銷!AA4 -> 數量 | AF4: =精餾產銷!AB4 -> 8/31 | AG4: =精餾產銷!AC4 -> 46295 | AH4: =精餾產銷!AD4 -> 46326 | AI4: =精餾產銷!AE4 -> 46356 | AL4: 最高 | AM4: 最低
A5: EBR-P1 | B5: TK631&TK699 | C5: =225+460 -> 685 | D5: =67+146.9 -> 213.9 | F5: 2 | G5: =IF(+D5+E5-F5<=0,0,+D5+E5-F5) -> 211.9 | H5: 306 | J5: =+SUMIF(秏料!$B$3:$B$133,$A5,秏料!$F$3:$F$133) -> 0 | K5: 1550 | M5: =+SUMIF(秏料!$B$3:$B$133,$A5,秏料!$H$3:$H$133) -> 0 | N5: 1550 | P5: =+SUMIF(秏料!$B$3:$B$133,$A5,秏料!$J$3:$J$133) -> 0 | Q5: 1550 | S5: =+SUMIF(秏料!$B$3:$B$133,$A5,秏料!$L$3:$L$133) -> 0 | T5: R01 | U5: 24~31 | V5: 350 | W5: R02 | X5: 1~31 | Y5: 1500 | Z5: R02 | AA5: 1~31 | AB5: 1500 | AC5: R02 | AD5: 1~30 | AE5: 1500 | AF5: =+G5-SUM(H5:J5)+SUM(V5:V5) -> 255.9 | AG5: =+AF5-SUM(K5:M5)+SUM(Y5:Y5) -> 205.9 | AH5: =+AG5-SUM(N5:P5)+SUM(AB5:AB5) -> 155.9 | AI5: =+AH5-SUM(Q5:S5)+SUM(AE5:AE5) -> 105.9 | AJ5: =+IF(SUM(G5,H5:S5,V5,Y5,AB5,AE5)=0,0,1) -> 1
A6: CPN-P1 | B6: TK634.TK653 | C6: =450 -> 450 | D6: =187+0 -> 187 | E6: 511 | G6: =IF(+D6+E6-F6<=0,0,+D6+E6-F6) -> 698 | J6: =+SUMIF(秏料!$B$3:$B$133,$A6,秏料!$F$3:$F$133) -> 0 | M6: =+SUMIF(秏料!$B$3:$B$133,$A6,秏料!$H$3:$H$133) -> 763 | N6: 0 | P6: =+SUMIF(秏料!$B$3:$B$133,$A6,秏料!$J$3:$J$133) -> 861 | Q6: 0 | S6: =+SUMIF(秏料!$B$3:$B$133,$A6,秏料!$L$3:$L$133) -> 861 | T6: R02 | U6: 24~31 | V6: 160 | W6: R01 | X6: 1~31 | Y6: 350 | Z6: R01 | AA6: 9~21 | AB6: =340 -> 340 | AC6: R01 | AD6: 1~30 | AE6: 340 | AF6: =+G6-SUM(H6:J6)+SUM(V6:V6)+200 -> 1058 | AG6: =+AF6-SUM(K6:M6)+SUM(Y6:Y6)+200 -> 845 | AH6: =+AG6-SUM(N6:P6)+SUM(AB6:AB6)+100 -> 424 | AI6: =+AH6-SUM(Q6:S6)+SUM(AE6:AE6)+100 -> 3 | AJ6: =+IF(SUM(G6,H6:S6,V6,Y6,AB6,AE6)=0,0,1) -> 1
A7: EBR-P2 | B7: TK655 | C7: 48 | D7: =0 -> 0 | F7: 1 | G7: =IF(+D7+E7-F7<=0,0,+D7+E7-F7) -> 0 | J7: =+SUMIF(秏料!$B$3:$B$133,$A7,秏料!$F$3:$F$133) -> 0 | M7: =+SUMIF(秏料!$B$3:$B$133,$A7,秏料!$H$3:$H$133) -> 0 | P7: =+SUMIF(秏料!$B$3:$B$133,$A7,秏料!$J$3:$J$133) -> 0 | S7: =+SUMIF(秏料!$B$3:$B$133,$A7,秏料!$L$3:$L$133) -> 0 | AF7: =+G7-SUM(H7:J7)+SUM(V7) -> 0 | AG7: =+AF7-SUM(K7:M7)+SUM(Y7) -> 0 | AH7: =+AG7-SUM(N7:P7)+SUM(AB7) -> 0 | AI7: =+AH7-SUM(Q7:S7)+SUM(AE7) -> 0 | AJ7: =+IF(SUM(G7,H7:S7,V7,Y7,AB7,AE7)=0,0,1) -> 0
A8: EBR95 | B8: TK653 | C8: 50 | D8: 36.9 | F8: 1 | G8: 37 | H8: 37 | J8: =+SUMIF(秏料!$B$3:$B$133,$A8,秏料!$F$3:$F$133) -> 0 | M8: =+SUMIF(秏料!$B$3:$B$133,$A8,秏料!$H$3:$H$133) -> 0 | N8: 35 | P8: =+SUMIF(秏料!$B$3:$B$133,$A8,秏料!$J$3:$J$133) -> 0 | Q8: 0 | S8: =+SUMIF(秏料!$B$3:$B$133,$A8,秏料!$L$3:$L$133) -> 0 | Z8: R01 | AA8: 3~7 | AB8: 35 | AF8: =+G8-SUM(H8:J8)+SUM(V8:V8) -> 0 | AG8: =+AF8-SUM(K8:M8)+SUM(Y8:Y8) -> 0 | AH8: =+AG8-SUM(N8:P8)+SUM(AB8:AB8) -> 0 | AI8: =+AH8-SUM(Q8:S8)+SUM(AE8:AE8) -> 0 | AJ8: =+IF(SUM(G8,H8:S8,V8,Y8,AB8,AE8)=0,0,1) -> 1
A9: Mixed Ether | B9: TK673.TK674 | C9: =58+58 -> 116 | D9: =0+0 -> 0 | F9: 1 | G9: =IF(+D9+E9-F9<=0,0,+D9+E9-F9) -> 0 | H9: 0 | J9: =+SUMIF(秏料!$B$3:$B$133,$A9,秏料!$F$3:$F$133) -> 0 | K9: 0 | M9: =+SUMIF(秏料!$B$3:$B$133,$A9,秏料!$H$3:$H$133) -> 0 | P9: =+SUMIF(秏料!$B$3:$B$133,$A9,秏料!$J$3:$J$133) -> 0 | S9: =+SUMIF(秏料!$B$3:$B$133,$A9,秏料!$L$3:$L$133) -> 0 | W9: R01 | X9: 15~19 | Y9: 80 | AF9: =+G9-SUM(H9:J9)+SUM(V9:V9) -> 0 | AG9: =+AF9-SUM(K9:M9)+SUM(Y9:Y9) -> 80 | AH9: =+AG9-SUM(N9:P9)+SUM(AB9:AB9) -> 80 | AI9: =+AH9-SUM(Q9:S9)+SUM(AE9:AE9) -> 80 | AJ9: =+IF(SUM(G9,H9:S9,V9,Y9,AB9,AE9)=0,0,1) -> 1
A10: DPM-B1 | B10: TK641 | C10: 115 | D10: 46.6 | F10: 1 | G10: =IF(+D10+E10-F10<=0,0,+D10+E10-F10) -> 45.6 | H10: 0 | J10: =+SUMIF(秏料!$B$3:$B$133,$A10,秏料!$F$3:$F$133) -> 0 | K10: 40 | M10: =+SUMIF(秏料!$B$3:$B$133,$A10,秏料!$H$3:$H$133) -> 0 | N10: 20 | Q10: 20 | Z10: R01 | AA10: 22~30 | AB10: 60 | AF10: =+G10-SUM(H10:J10)+SUM(V10:V10) -> 45.6 | AG10: =+AF10-SUM(K10:M10)+SUM(Y10:Y10) -> 5.6 | AH10: =+AG10-SUM(N10:P10)+SUM(AB10:AB10) -> 45.6 | AI10: =+AH10-SUM(Q10:S10)+SUM(AE10:AE10) -> 25.6 | AJ10: =+IF(SUM(G10,H10:S10,V10,Y10,AB10,AE10)=0,0,1) -> 1
A11: EBR-P4 | B11: TK-673&TK674 | C11: =65+54 -> 119 | D11: 0 | F11: 1 | G11: =IF(+D11+E11-F11<=0,0,+D11+E11-F11) -> 0 | H11: 0 | J11: =+SUMIF(秏料!$B$3:$B$133,$A11,秏料!$F$3:$F$133) -> 0 | M11: =+SUMIF(秏料!$B$3:$B$133,$A11,秏料!$H$3:$H$133) -> 0 | P11: =+SUMIF(秏料!$B$3:$B$133,$A11,秏料!$J$3:$J$133) -> 0 | S11: =+SUMIF(秏料!$B$3:$B$133,$A11,秏料!$L$3:$L$133) -> 0 | AF11: =+G11-SUM(H11:J11)+SUM(V11) -> 0 | AG11: =+AF11-SUM(K11:M11)+SUM(Y11) -> 0 | AH11: =+AG11-SUM(N11:P11)+SUM(AB11) -> 0 | AI11: =+AH11-SUM(Q11:S11)+SUM(AE11) -> 0 | AJ11: =+IF(SUM(G11,H11:S11,V11,Y11,AB11,AE11)=0,0,1) -> 0
G12: =+D12+E12-F12 -> 0 | J12: =+SUMIF(秏料!$B$3:$B$133,$A12,秏料!$F$3:$F$133) -> 0 | M12: =+SUMIF(秏料!$B$3:$B$133,$A12,秏料!$H$3:$H$133) -> 0 | P12: =+SUMIF(秏料!$B$3:$B$133,$A12,秏料!$J$3:$J$133) -> 0 | S12: =+SUMIF(秏料!$B$3:$B$133,$A12,秏料!$L$3:$L$133) -> 0 | AF12: =+G12-SUM(H12:J12)+SUM(V12) -> 0 | AG12: =+AF12-SUM(K12:M12)+SUM(Y12) -> 0 | AH12: =+AG12-SUM(N12:P12)+SUM(AB12) -> 0 | AI12: =+AH12-SUM(Q12:S12)+SUM(AE12) -> 0 | AJ12: =+IF(SUM(G12,H12:S12,V12,Y12,AB12,AE12)=0,0,1) -> 0
G13: =+D13+E13-F13 -> 0 | J13: =+SUMIF(秏料!$B$3:$B$133,$A13,秏料!$F$3:$F$133) -> 0 | M13: =+SUMIF(秏料!$B$3:$B$133,$A13,秏料!$H$3:$H$133) -> 0 | P13: =+SUMIF(秏料!$B$3:$B$133,$A13,秏料!$J$3:$J$133) -> 0 | S13: =+SUMIF(秏料!$B$3:$B$133,$A13,秏料!$L$3:$L$133) -> 0 | AF13: =+G13-SUM(H13:J13)+SUM(V13) -> 0 | AG13: =+AF13-SUM(K13:M13)+SUM(Y13) -> 0 | AH13: =+AG13-SUM(N13:P13)+SUM(AB13) -> 0 | AI13: =+AH13-SUM(Q13:S13)+SUM(AE13) -> 0 | AJ13: =+IF(SUM(G13,H13:S13,V13,Y13,AB13,AE13)=0,0,1) -> 0
G14: =IF(+D14+E14-F14<=0,0,+D14+E14-F14) -> 0 | J14: =+SUMIF(秏料!$B$3:$B$133,$A14,秏料!$F$3:$F$133) -> 0 | M14: =+SUMIF(秏料!$B$3:$B$133,$A14,秏料!$H$3:$H$133) -> 0 | P14: =+SUMIF(秏料!$B$3:$B$133,$A14,秏料!$J$3:$J$133) -> 0 | S14: =+SUMIF(秏料!$B$3:$B$133,$A14,秏料!$L$3:$L$133) -> 0 | AF14: =+G14-SUM(H14:J14)+SUM(V14) -> 0 | AG14: =+AF14-SUM(K14:M14)+SUM(Y14) -> 0 | AH14: =+AG14-SUM(N14:P14)+SUM(AB14) -> 0 | AI14: =+AH14-SUM(Q14:S14)+SUM(AE14) -> 0 | AJ14: =+IF(SUM(G14,H14:S14,V14,Y14,AB14,AE14)=0,0,1) -> 0
G15: =IF(+D15+E15-F15<=0,0,+D15+E15-F15) -> 0 | J15: =+SUMIF(秏料!$B$3:$B$133,$A15,秏料!$F$3:$F$133) -> 0 | M15: =+SUMIF(秏料!$B$3:$B$133,$A15,秏料!$H$3:$H$133) -> 0 | P15: =+SUMIF(秏料!$B$3:$B$133,$A15,秏料!$J$3:$J$133) -> 0 | S15: =+SUMIF(秏料!$B$3:$B$133,$A15,秏料!$L$3:$L$133) -> 0 | AF15: =+G15-SUM(H15:J15)+SUM(V15:V15) -> 0 | AG15: =+AF15-SUM(K15:M15)+SUM(Y15:Y15) -> 0 | AH15: =+AG15-SUM(N15:P15)+SUM(AB15:AB15) -> 0 | AI15: =+AH15-SUM(Q15:S15)+SUM(AE15:AE15) -> 0 | AJ15: =+IF(SUM(G15,H15:S15,V15,Y15,AB15,AE15)=0,0,1) -> 0
G16: =IF(+D16+E16-F16<=0,0,+D16+E16-F16) -> 0 | J16: =+SUMIF(秏料!$B$3:$B$133,$A16,秏料!$F$3:$F$133) -> 0 | M16: =+SUMIF(秏料!$B$3:$B$133,$A16,秏料!$H$3:$H$133) -> 0 | P16: =+SUMIF(秏料!$B$3:$B$133,$A16,秏料!$J$3:$J$133) -> 0 | S16: =+SUMIF(秏料!$B$3:$B$133,$A16,秏料!$L$3:$L$133) -> 0 | AF16: =+G16-SUM(H16:J16)+SUM(V16) -> 0 | AG16: =+AF16-SUM(K16:M16)+SUM(Y16) -> 0 | AH16: =+AG16-SUM(N16:P16)+SUM(AB16) -> 0 | AI16: =+AH16-SUM(Q16:S16)+SUM(AE16) -> 0 | AJ16: =+IF(SUM(G16,H16:S16,V16,Y16,AB16,AE16)=0,0,1) -> 0
G17: =IF(+D17+E17-F17<=0,0,+D17+E17-F17) -> 0 | J17: =+SUMIF(秏料!$B$3:$B$133,$A17,秏料!$F$3:$F$133) -> 0 | M17: =+SUMIF(秏料!$B$3:$B$133,$A17,秏料!$H$3:$H$133) -> 0 | P17: =+SUMIF(秏料!$B$3:$B$133,$A17,秏料!$J$3:$J$133) -> 0 | S17: =+SUMIF(秏料!$B$3:$B$133,$A17,秏料!$L$3:$L$133) -> 0 | AF17: =+G17-SUM(H17:J17)+SUM(V17:V17) -> 0 | AG17: =+AF17-SUM(K17:M17)+SUM(Y17:Y17) -> 0 | AH17: =+AG17-SUM(N17:P17)+SUM(AB17:AB17) -> 0 | AI17: =+AH17-SUM(Q17:S17)+SUM(AE17:AE17) -> 0 | AJ17: =+IF(SUM(G17,H17:S17,V17,Y17,AB17,AE17)=0,0,1) -> 0
G18: =IF(+D18+E18-F18<=0,0,+D18+E18-F18) -> 0 | J18: =+SUMIF(秏料!$B$3:$B$133,$A18,秏料!$F$3:$F$133) -> 0 | M18: =+SUMIF(秏料!$B$3:$B$133,$A18,秏料!$H$3:$H$133) -> 0 | P18: =+SUMIF(秏料!$B$3:$B$133,$A18,秏料!$J$3:$J$133) -> 0 | S18: =+SUMIF(秏料!$B$3:$B$133,$A18,秏料!$L$3:$L$133) -> 0 | AF18: =+G18-SUM(H18:J18)+SUM(V18) -> 0 | AG18: =+AF18-SUM(K18:M18)+SUM(Y18) -> 0 | AH18: =+AG18-SUM(N18:P18)+SUM(AB18) -> 0 | AI18: =+AH18-SUM(Q18:S18)+SUM(AE18) -> 0 | AJ18: =+IF(SUM(G18,H18:S18,V18,Y18,AB18,AE18)=0,0,1) -> 0
G19: =IF(+D19+E19-F19<=0,0,+D19+E19-F19) -> 0 | J19: =+SUMIF(秏料!$B$3:$B$133,$A19,秏料!$F$3:$F$133) -> 0 | M19: =+SUMIF(秏料!$B$3:$B$133,$A19,秏料!$H$3:$H$133) -> 0 | P19: =+SUMIF(秏料!$B$3:$B$133,$A19,秏料!$J$3:$J$133) -> 0 | S19: =+SUMIF(秏料!$B$3:$B$133,$A19,秏料!$L$3:$L$133) -> 0 | AF19: =+G19-SUM(H19:J19)+SUM(V19) -> 0 | AG19: =+AF19-SUM(K19:M19)+SUM(Y19) -> 0 | AH19: =+AG19-SUM(N19:P19)+SUM(AB19) -> 0 | AI19: =+AH19-SUM(Q19:S19)+SUM(AE19) -> 0 | AJ19: =+IF(SUM(G19,H19:S19,V19,Y19,AB19,AE19)=0,0,1) -> 0
G20: =IF(+D20+E20-F20<=0,0,+D20+E20-F20) -> 0 | J20: =+SUMIF(秏料!$B$3:$B$133,$A20,秏料!$F$3:$F$133) -> 0 | M20: =+SUMIF(秏料!$B$3:$B$133,$A20,秏料!$H$3:$H$133) -> 0 | P20: =+SUMIF(秏料!$B$3:$B$133,$A20,秏料!$J$3:$J$133) -> 0 | S20: =+SUMIF(秏料!$B$3:$B$133,$A20,秏料!$L$3:$L$133) -> 0 | AF20: =+G20-SUM(H20:J20)+SUM(V20) -> 0 | AG20: =+AF20-SUM(K20:M20)+SUM(Y20) -> 0 | AH20: =+AG20-SUM(N20:P20)+SUM(AB20) -> 0 | AI20: =+AH20-SUM(Q20:S20)+SUM(AE20) -> 0 | AJ20: =+IF(SUM(G20,H20:S20,V20,Y20,AB20,AE20)=0,0,1) -> 0
G21: =IF(+D21+E21-F21<=0,0,+D21+E21-F21) -> 0 | J21: =+SUMIF(秏料!$B$3:$B$133,$A21,秏料!$F$3:$F$133) -> 0 | M21: =+SUMIF(秏料!$B$3:$B$133,$A21,秏料!$H$3:$H$133) -> 0 | P21: =+SUMIF(秏料!$B$3:$B$133,$A21,秏料!$J$3:$J$133) -> 0 | S21: =+SUMIF(秏料!$B$3:$B$133,$A21,秏料!$L$3:$L$133) -> 0 | AF21: =+G21-SUM(H21:J21)+SUM(V21) -> 0 | AG21: =+AF21-SUM(K21:M21)+SUM(Y21) -> 0 | AH21: =+AG21-SUM(N21:P21)+SUM(AB21) -> 0 | AI21: =+AH21-SUM(Q21:S21)+SUM(AE21) -> 0 | AJ21: =+IF(SUM(G21,H21:S21,V21,Y21,AB21,AE21)=0,0,1) -> 0
G22: =IF(+D22+E22-F22<=0,0,+D22+E22-F22) -> 0 | J22: =+SUMIF(秏料!$B$3:$B$133,$A22,秏料!$F$3:$F$133) -> 0 | M22: =+SUMIF(秏料!$B$3:$B$133,$A22,秏料!$H$3:$H$133) -> 0 | P22: =+SUMIF(秏料!$B$3:$B$133,$A22,秏料!$J$3:$J$133) -> 0 | S22: =+SUMIF(秏料!$B$3:$B$133,$A22,秏料!$L$3:$L$133) -> 0 | AF22: =+G22-SUM(H22:J22)+SUM(V22) -> 0 | AG22: =+AF22-SUM(K22:M22)+SUM(Y22) -> 0 | AH22: =+AG22-SUM(N22:P22)+SUM(AB22) -> 0 | AI22: =+AH22-SUM(Q22:S22)+SUM(AE22) -> 0 | AJ22: =+IF(SUM(G22,H22:S22,V22,Y22,AB22,AE22)=0,0,1) -> 0
G23: =IF(+D23+E23-F23<=0,0,+D23+E23-F23) -> 0 | J23: =+SUMIF(秏料!$B$3:$B$133,$A23,秏料!$F$3:$F$133) -> 0 | M23: =+SUMIF(秏料!$B$3:$B$133,$A23,秏料!$H$3:$H$133) -> 0 | P23: =+SUMIF(秏料!$B$3:$B$133,$A23,秏料!$J$3:$J$133) -> 0 | S23: =+SUMIF(秏料!$B$3:$B$133,$A23,秏料!$L$3:$L$133) -> 0 | T23: =IF(V23=0,0,T$4) -> 0 | V23: =+H23+J23 -> 0 | W23: =IF(Y23=0,0,W$4) -> 0 | Y23: =+K23+M23 -> 0 | Z23: =IF(AB23=0,0,Z$4) -> 0 | AB23: =+N23+P23 -> 0 | AC23: =IF(AE23=0,0,AC$4) -> 0 | AE23: =+Q23+S23 -> 0 | AF23: =+G23-SUM(H23:J23)+SUM(V23) -> 0 | AG23: =+AF23-SUM(K23:M23)+SUM(Y23) -> 0 | AH23: =+AG23-SUM(N23:P23)+SUM(AB23) -> 0 | AI23: =+AH23-SUM(Q23:S23)+SUM(AE23) -> 0 | AJ23: =+IF(SUM(G23,H23:S23,V23,Y23,AB23,AE23)=0,0,1) -> 0
G24: =IF(+D24+E24-F24<=0,0,+D24+E24-F24) -> 0 | J24: =+SUMIF(秏料!$B$3:$B$133,$A24,秏料!$F$3:$F$133) -> 0 | M24: =+SUMIF(秏料!$B$3:$B$133,$A24,秏料!$H$3:$H$133) -> 0 | P24: =+SUMIF(秏料!$B$3:$B$133,$A24,秏料!$J$3:$J$133) -> 0 | S24: =+SUMIF(秏料!$B$3:$B$133,$A24,秏料!$L$3:$L$133) -> 0 | T24: =IF(V24=0,0,T$4) -> 0 | V24: =+H24+J24 -> 0 | W24: =IF(Y24=0,0,W$4) -> 0 | Y24: =+K24+M24 -> 0 | Z24: =IF(AB24=0,0,Z$4) -> 0 | AB24: =+N24+P24 -> 0 | AC24: =IF(AE24=0,0,AC$4) -> 0 | AE24: =+Q24+S24 -> 0 | AF24: =+G24-SUM(H24:J24)+SUM(V24) -> 0 | AG24: =+AF24-SUM(K24:M24)+SUM(Y24) -> 0 | AH24: =+AG24-SUM(N24:P24)+SUM(AB24) -> 0 | AI24: =+AH24-SUM(Q24:S24)+SUM(AE24) -> 0 | AJ24: =+IF(SUM(G24,H24:S24,V24,Y24,AB24,AE24)=0,0,1) -> 0
G25: =IF(+D25+E25-F25<=0,0,+D25+E25-F25) -> 0 | J25: =+SUMIF(秏料!$B$3:$B$133,$A25,秏料!$F$3:$F$133) -> 0 | M25: =+SUMIF(秏料!$B$3:$B$133,$A25,秏料!$H$3:$H$133) -> 0 | P25: =+SUMIF(秏料!$B$3:$B$133,$A25,秏料!$J$3:$J$133) -> 0 | S25: =+SUMIF(秏料!$B$3:$B$133,$A25,秏料!$L$3:$L$133) -> 0 | T25: =IF(V25=0,0,T$4) -> 0 | V25: =+H25+J25 -> 0 | W25: =IF(Y25=0,0,W$4) -> 0 | Y25: =+K25+M25 -> 0 | Z25: =IF(AB25=0,0,Z$4) -> 0 | AB25: =+N25+P25 -> 0 | AC25: =IF(AE25=0,0,AC$4) -> 0 | AE25: =+Q25+S25 -> 0 | AF25: =+G25-SUM(H25:J25)+SUM(V25) -> 0 | AG25: =+AF25-SUM(K25:M25)+SUM(Y25) -> 0 | AH25: =+AG25-SUM(N25:P25)+SUM(AB25) -> 0 | AI25: =+AH25-SUM(Q25:S25)+SUM(AE25) -> 0 | AJ25: =+IF(SUM(G25,H25:S25,V25,Y25,AB25,AE25)=0,0,1) -> 0
G26: =IF(+D26+E26-F26<=0,0,+D26+E26-F26) -> 0 | J26: =+SUMIF(秏料!$B$3:$B$133,$A26,秏料!$F$3:$F$133) -> 0 | M26: =+SUMIF(秏料!$B$3:$B$133,$A26,秏料!$H$3:$H$133) -> 0 | P26: =+SUMIF(秏料!$B$3:$B$133,$A26,秏料!$J$3:$J$133) -> 0 | S26: =+SUMIF(秏料!$B$3:$B$133,$A26,秏料!$L$3:$L$133) -> 0 | T26: =IF(V26=0,0,T$4) -> 0 | V26: =+H26+J26 -> 0 | W26: =IF(Y26=0,0,W$4) -> 0 | Y26: =+K26+M26 -> 0 | Z26: =IF(AB26=0,0,Z$4) -> 0 | AB26: =+N26+P26 -> 0 | AC26: =IF(AE26=0,0,AC$4) -> 0 | AE26: =+Q26+S26 -> 0 | AF26: =+G26-SUM(H26:J26)+SUM(V26) -> 0 | AG26: =+AF26-SUM(K26:M26)+SUM(Y26) -> 0 | AH26: =+AG26-SUM(N26:P26)+SUM(AB26) -> 0 | AI26: =+AH26-SUM(Q26:S26)+SUM(AE26) -> 0 | AJ26: =+IF(SUM(G26,H26:S26,V26,Y26,AB26,AE26)=0,0,1) -> 0
G27: =IF(+D27+E27-F27<=0,0,+D27+E27-F27) -> 0 | J27: =+SUMIF(秏料!$B$3:$B$133,$A27,秏料!$F$3:$F$133) -> 0 | M27: =+SUMIF(秏料!$B$3:$B$133,$A27,秏料!$H$3:$H$133) -> 0 | P27: =+SUMIF(秏料!$B$3:$B$133,$A27,秏料!$J$3:$J$133) -> 0 | S27: =+SUMIF(秏料!$B$3:$B$133,$A27,秏料!$L$3:$L$133) -> 0 | T27: =IF(V27=0,0,T$4) -> 0 | V27: =+H27+J27 -> 0 | W27: =IF(Y27=0,0,W$4) -> 0 | Y27: =+K27+M27 -> 0 | Z27: =IF(AB27=0,0,Z$4) -> 0 | AB27: =+N27+P27 -> 0 | AC27: =IF(AE27=0,0,AC$4) -> 0 | AE27: =+Q27+S27 -> 0 | AF27: =+G27-SUM(H27:J27)+SUM(V27) -> 0 | AG27: =+AF27-SUM(K27:M27)+SUM(Y27) -> 0 | AH27: =+AG27-SUM(N27:P27)+SUM(AB27) -> 0 | AI27: =+AH27-SUM(Q27:S27)+SUM(AE27) -> 0 | AJ27: =+IF(SUM(G27,H27:S27,V27,Y27,AB27,AE27)=0,0,1) -> 0
G28: =IF(+D28+E28-F28<=0,0,+D28+E28-F28) -> 0 | J28: =+SUMIF(秏料!$B$3:$B$133,$A28,秏料!$F$3:$F$133) -> 0 | M28: =+SUMIF(秏料!$B$3:$B$133,$A28,秏料!$H$3:$H$133) -> 0 | P28: =+SUMIF(秏料!$B$3:$B$133,$A28,秏料!$J$3:$J$133) -> 0 | S28: =+SUMIF(秏料!$B$3:$B$133,$A28,秏料!$L$3:$L$133) -> 0 | T28: =IF(V28=0,0,T$4) -> 0 | V28: =+H28+J28 -> 0 | W28: =IF(Y28=0,0,W$4) -> 0 | Y28: =+K28+M28 -> 0 | Z28: =IF(AB28=0,0,Z$4) -> 0 | AB28: =+N28+P28 -> 0 | AC28: =IF(AE28=0,0,AC$4) -> 0 | AE28: =+Q28+S28 -> 0 | AF28: =+G28-SUM(H28:J28)+SUM(V28) -> 0 | AG28: =+AF28-SUM(K28:M28)+SUM(Y28) -> 0 | AH28: =+AG28-SUM(N28:P28)+SUM(AB28) -> 0 | AI28: =+AH28-SUM(Q28:S28)+SUM(AE28) -> 0 | AJ28: =+IF(SUM(G28,H28:S28,V28,Y28,AB28,AE28)=0,0,1) -> 0
J29: =+SUMIF(秏料!$B$3:$B$133,$A29,秏料!$F$3:$F$133) -> 0 | M29: =+SUMIF(秏料!$B$3:$B$133,$A29,秏料!$H$3:$H$133) -> 0 | P29: =+SUMIF(秏料!$B$3:$B$133,$A29,秏料!$J$3:$J$133) -> 0 | S29: =+SUMIF(秏料!$B$3:$B$133,$A29,秏料!$L$3:$L$133) -> 0 | T29: =IF(V29=0,0,T$4) -> 0 | V29: =+H29+J29 -> 0 | W29: =IF(Y29=0,0,W$4) -> 0 | Y29: =+K29+M29 -> 0 | Z29: =IF(AB29=0,0,Z$4) -> 0 | AB29: =+N29+P29 -> 0 | AC29: =IF(AE29=0,0,AC$4) -> 0 | AE29: =+Q29+S29 -> 0 | AF29: =+G29-SUM(H29:J29)+SUM(V29) -> 0 | AG29: =+AF29-SUM(K29:M29)+SUM(Y29) -> 0 | AH29: =+AG29-SUM(N29:P29)+SUM(AB29) -> 0 | AI29: =+AH29-SUM(Q29:S29)+SUM(AE29) -> 0 | AJ29: =+IF(SUM(G29,H29:S29,V29,Y29,AB29,AE29)=0,0,1) -> 0
G30: =+D30+E30-F30 -> 0 | J30: =+SUMIF(秏料!$B$3:$B$133,$A30,秏料!$F$3:$F$133) -> 0 | M30: =+SUMIF(秏料!$B$3:$B$133,$A30,秏料!$H$3:$H$133) -> 0 | P30: =+SUMIF(秏料!$B$3:$B$133,$A30,秏料!$J$3:$J$133) -> 0 | S30: =+SUMIF(秏料!$B$3:$B$133,$A30,秏料!$L$3:$L$133) -> 0 | T30: =IF(V30=0,0,T$4) -> 0 | V30: =+H30+J30 -> 0 | W30: =IF(Y30=0,0,W$4) -> 0 | Y30: =+K30+M30 -> 0 | Z30: =IF(AB30=0,0,Z$4) -> 0 | AB30: =+N30+P30 -> 0 | AC30: =IF(AE30=0,0,AC$4) -> 0 | AE30: =+Q30+S30 -> 0 | AF30: =+G30-SUM(H30:J30)+SUM(V30) -> 0 | AG30: =+AF30-SUM(K30:M30)+SUM(Y30) -> 0 | AH30: =+AG30-SUM(N30:P30)+SUM(AB30) -> 0 | AI30: =+AH30-SUM(Q30:S30)+SUM(AE30) -> 0 | AJ30: =+IF(SUM(G30,H30:S30,V30,Y30,AB30,AE30)=0,0,1) -> 0
G31: =+D31+E31-F31 -> 0 | J31: =+SUMIF(秏料!$B$3:$B$133,$A31,秏料!$F$3:$F$133) -> 0 | M31: =+SUMIF(秏料!$B$3:$B$133,$A31,秏料!$H$3:$H$133) -> 0 | P31: =+SUMIF(秏料!$B$3:$B$133,$A31,秏料!$J$3:$J$133) -> 0 | S31: =+SUMIF(秏料!$B$3:$B$133,$A31,秏料!$L$3:$L$133) -> 0 | T31: =IF(V31=0,0,T$4) -> 0 | V31: =+H31+J31 -> 0 | W31: =IF(Y31=0,0,W$4) -> 0 | Y31: =+K31+M31 -> 0 | Z31: =IF(AB31=0,0,Z$4) -> 0 | AB31: =+N31+P31 -> 0 | AC31: =IF(AE31=0,0,AC$4) -> 0 | AE31: =+Q31+S31 -> 0 | AF31: =+G31-SUM(H31:J31)+SUM(V31) -> 0 | AG31: =+AF31-SUM(K31:M31)+SUM(Y31) -> 0 | AH31: =+AG31-SUM(N31:P31)+SUM(AB31) -> 0 | AI31: =+AH31-SUM(Q31:S31)+SUM(AE31) -> 0 | AJ31: =+IF(SUM(G31,H31:S31,V31,Y31,AB31,AE31)=0,0,1) -> 0
G32: =+D32+E32-F32 -> 0 | J32: =+SUMIF(秏料!$B$3:$B$133,$A32,秏料!$F$3:$F$133) -> 0 | M32: =+SUMIF(秏料!$B$3:$B$133,$A32,秏料!$H$3:$H$133) -> 0 | P32: =+SUMIF(秏料!$B$3:$B$133,$A32,秏料!$J$3:$J$133) -> 0 | S32: =+SUMIF(秏料!$B$3:$B$133,$A32,秏料!$L$3:$L$133) -> 0 | T32: =IF(V32=0,0,T$4) -> 0 | V32: =+H32+J32 -> 0 | W32: =IF(Y32=0,0,W$4) -> 0 | Y32: =+K32+M32 -> 0 | Z32: =IF(AB32=0,0,Z$4) -> 0 | AB32: =+N32+P32 -> 0 | AC32: =IF(AE32=0,0,AC$4) -> 0 | AE32: =+Q32+S32 -> 0 | AF32: =+G32-SUM(H32:J32)+SUM(V32) -> 0 | AG32: =+AF32-SUM(K32:M32)+SUM(Y32) -> 0 | AH32: =+AG32-SUM(N32:P32)+SUM(AB32) -> 0 | AI32: =+AH32-SUM(Q32:S32)+SUM(AE32) -> 0 | AJ32: =+IF(SUM(G32,H32:S32,V32,Y32,AB32,AE32)=0,0,1) -> 0
G33: =+D33+E33-F33 -> 0 | J33: =+SUMIF(秏料!$B$3:$B$133,$A33,秏料!$F$3:$F$133) -> 0 | M33: =+SUMIF(秏料!$B$3:$B$133,$A33,秏料!$H$3:$H$133) -> 0 | P33: =+SUMIF(秏料!$B$3:$B$133,$A33,秏料!$J$3:$J$133) -> 0 | S33: =+SUMIF(秏料!$B$3:$B$133,$A33,秏料!$L$3:$L$133) -> 0 | T33: =IF(V33=0,0,T$4) -> 0 | V33: =+H33+J33 -> 0 | W33: =IF(Y33=0,0,W$4) -> 0 | Y33: =+K33+M33 -> 0 | Z33: =IF(AB33=0,0,Z$4) -> 0 | AB33: =+N33+P33 -> 0 | AC33: =IF(AE33=0,0,AC$4) -> 0 | AE33: =+Q33+S33 -> 0 | AF33: =+G33-SUM(H33:J33)+SUM(V33) -> 0 | AG33: =+AF33-SUM(K33:M33)+SUM(Y33) -> 0 | AH33: =+AG33-SUM(N33:P33)+SUM(AB33) -> 0 | AI33: =+AH33-SUM(Q33:S33)+SUM(AE33) -> 0 | AJ33: =+IF(SUM(G33,H33:S33,V33,Y33,AB33,AE33)=0,0,1) -> 0
A34: =精餾產銷!A59 -> 原料品名 | B34: =精餾產銷!B59 -> 0 | C34: =精餾產銷!C59 -> 儲槽 容量 (MT) | D34: =精餾產銷!D59 -> 0 | E34: =精餾產銷!E59 -> 0 | F34: =精餾產銷!F59 -> 0 | G34: =精餾產銷!G59 -> 46258 | H34: =精餾產銷!H59 -> 銷售 | T34: =精餾產銷!P59 -> 耗用量 | X34: =精餾產銷!T59 -> 進貨 | AB34: =精餾產銷!X59 -> 其他入庫 | AF34: =精餾產銷!AB59 -> 庫存 | AJ34: =+IF(SUM(G34,H34:S34,V34,Y34,AB34,AE34)=0,0,1) -> 1
B35: =精餾產銷!B60 -> 0 | D35: =精餾產銷!D60 -> 0 | E35: =精餾產銷!E60 -> 0 | F35: =精餾產銷!F60 -> 0 | H35: =精餾產銷!H60 -> 08/24~08/31 | K35: =精餾產銷!J60 -> 46295 | N35: =精餾產銷!L60 -> 46326 | Q35: =精餾產銷!N60 -> 46356 | T35: =精餾產銷!P60 -> 24~31 | U35: =精餾產銷!Q60 -> 46295 | V35: =精餾產銷!R60 -> 46326 | W35: =精餾產銷!S60 -> 46356 | X35: =精餾產銷!T60 -> 24~31 | Y35: =精餾產銷!U60 -> 46295 | Z35: =精餾產銷!V60 -> 46326 | AA35: =精餾產銷!W60 -> 46356 | ... AI35: =精餾產銷!AE60 -> 46356 | AJ35: =+IF(SUM(G35,H35:S35,V35,Y35,AB35,AE35)=0,0,1) -> 1
A36: EBR-P1R | B36: TKC01-TKC09 | C36: =42*8 -> 336 | D36: =47.5+36+38+25.7+0+7.9+0+37.8+31.5 -> 224.4 | F36: 0 | G36: =IF(+D36+E36-F36<=0,0,+D36+E36-F36) -> 224.4 | T36: =+SUMIF(秏料!$B$3:$B$133,$A36,秏料!$F$3:$F$133) -> 371 | U36: =+SUMIF(秏料!$B$3:$B$133,$A36,秏料!$H$3:$H$133) -> 1590 | V36: =+SUMIF(秏料!$B$3:$B$133,$A36,秏料!$J$3:$J$133) -> 1590 | W36: =+SUMIF(秏料!$B$3:$B$133,$A36,秏料!$L$3:$L$133) -> 1590 | X36: 526 | Y36: 1600 | Z36: 1600 | AA36: 1600 | AF36: =+G36-SUM(H36:J36,T36)+SUM(X36,AB36) -> 379.4 | AG36: =+AF36-SUM(K36:M36,U36)+SUM(Y36,AC36) -> 389.4 | AH36: =+AG36-SUM(N36:P36,V36)+SUM(Z36,AD36) -> 399.4 | AI36: =+AH36-SUM(Q36:S36,W36)+SUM(AA36,AE36) -> 409.4 | AJ36: =+IF(SUM(G36,H36:S36,V36,Y36,AB36,AE36)=0,0,1) -> 1
A37: NBAC-P1R | B37: TK658.TK659 | C37: 100 | D37: =14.7+18.9 -> 33.6 | F37: 0 | G37: =IF(+D37+E37-F37<=0,0,+D37+E37-F37) -> 33.6 | H37: 94 | K37: 350 | N37: 300 | Q37: 300 | T37: =+SUMIF(秏料!$B$3:$B$133,$A37,秏料!$F$3:$F$133) -> 0 | U37: =+SUMIF(秏料!$B$3:$B$133,$A37,秏料!$H$3:$H$133) -> 0 | V37: =+SUMIF(秏料!$B$3:$B$133,$A37,秏料!$J$3:$J$133) -> 0 | W37: =+SUMIF(秏料!$B$3:$B$133,$A37,秏料!$L$3:$L$133) -> 0 | X37: 105 | Y37: 350 | Z37: 350 | AA37: 350 | AF37: =+G37-SUM(H37:J37,T37)+SUM(X37,AB37) -> 44.6 | AG37: =+AF37-SUM(K37:M37,U37)+SUM(Y37,AC37) -> 44.6 | AH37: =+AG37-SUM(N37:P37,V37)+SUM(Z37,AD37) -> 94.6 | AI37: =+AH37-SUM(Q37:S37,W37)+SUM(AA37,AE37) -> 144.6 | AJ37: =+IF(SUM(G37,H37:S37,V37,Y37,AB37,AE37)=0,0,1) -> 1
A38: 1NBAC-P2 | G38: =IF(+D38+E38-F38<=0,0,+D38+E38-F38) -> 0 | T38: =+SUMIF(秏料!$B$3:$B$133,$A38,秏料!$F$3:$F$133) -> 0 | U38: =+SUMIF(秏料!$B$3:$B$133,$A38,秏料!$H$3:$H$133) -> 0 | V38: =+SUMIF(秏料!$B$3:$B$133,$A38,秏料!$J$3:$J$133) -> 0 | W38: =+SUMIF(秏料!$B$3:$B$133,$A38,秏料!$L$3:$L$133) -> 0 | AF38: =+G38-SUM(H38:J38,T38)+SUM(X38,AB38) -> 0 | AG38: =+AF38-SUM(K38:M38,U38)+SUM(Y38,AC38) -> 0 | AH38: =+AG38-SUM(N38:P38,V38)+SUM(Z38,AD38) -> 0 | AI38: =+AH38-SUM(Q38:S38,W38)+SUM(AA38,AE38) -> 0 | AJ38: =+IF(SUM(G38,H38:S38,V38,Y38,AB38,AE38)=0,0,1) -> 0
F39: 0 | G39: =IF(+D39+E39-F39<=0,0,+D39+E39-F39) -> 0 | T39: =+SUMIF(秏料!$B$3:$B$133,$A39,秏料!$F$3:$F$133) -> 0 | U39: =+SUMIF(秏料!$B$3:$B$133,$A39,秏料!$H$3:$H$133) -> 0 | V39: =+SUMIF(秏料!$B$3:$B$133,$A39,秏料!$J$3:$J$133) -> 0 | W39: =+SUMIF(秏料!$B$3:$B$133,$A39,秏料!$L$3:$L$133) -> 0 | AF39: =+G39-SUM(H39:J39,T39)+SUM(X39,AB39) -> 0 | AG39: =+AF39-SUM(K39:M39,U39)+SUM(Y39,AC39) -> 0 | AH39: =+AG39-SUM(N39:P39,V39)+SUM(Z39,AD39) -> 0 | AI39: =+AH39-SUM(Q39:S39,W39)+SUM(AA39,AE39) -> 0 | AJ39: =+IF(SUM(G39,H39:S39,V39,Y39,AB39,AE39)=0,0,1) -> 0
A40: 1EBR-P2 | C40: 33 | G40: =IF(+D40+E40-F40<=0,0,+D40+E40-F40) -> 0 | T40: =+SUMIF(秏料!$B$3:$B$133,$A40,秏料!$F$3:$F$133) -> 0 | U40: =+SUMIF(秏料!$B$3:$B$133,$A40,秏料!$H$3:$H$133) -> 0 | V40: =+SUMIF(秏料!$B$3:$B$133,$A40,秏料!$J$3:$J$133) -> 0 | W40: =+SUMIF(秏料!$B$3:$B$133,$A40,秏料!$L$3:$L$133) -> 0 | AF40: =+G40-SUM(H40:J40,T40)+SUM(X40,AB40) -> 0 | AG40: =+AF40-SUM(K40:M40,U40)+SUM(Y40,AC40) -> 0 | AH40: =+AG40-SUM(N40:P40,V40)+SUM(Z40,AD40) -> 0 | AI40: =+AH40-SUM(Q40:S40,W40)+SUM(AA40,AE40) -> 0 | AJ40: =+IF(SUM(G40,H40:S40,V40,Y40,AB40,AE40)=0,0,1) -> 0
...

Sheet 調配產銷
A1: 產銷計劃表(調配)
A2: 單位：MT | AE2: =+"日期："&TEXT($G$3,"YYYY/MM/DD") -> 日期：2026/08/24
A3: =精餾產銷!A3 -> 成品品名 | B3: =精餾產銷!B3 -> 存放位置 (隱藏) | C3: =精餾產銷!C3 -> 儲槽 容量 (MT) | D3: =精餾產銷!D3 -> 資材 | E3: =精餾產銷!E3 -> 製2 | F3: =精餾產銷!F3 -> 桶底 | G3: =精餾產銷!G3 -> 46258 | H3: =精餾產銷!H3 -> 08/24~08/31 | J3: =精餾產銷!J3 -> 46295 | L3: =精餾產銷!L3 -> 46326 | N3: =精餾產銷!N3 -> 46356 | P3: =精餾產銷!P3 -> 生產量 | AB3: =精餾產銷!AB3 -> 庫存 | AH3: 安全庫存量
D4: =精餾產銷!D4 -> 庫存 | E4: =精餾產銷!E4 -> 庫存 | H4: =精餾產銷!H4 -> 銷售 | I4: =精餾產銷!I4 -> 耗用 | J4: =精餾產銷!J4 -> 銷售 | K4: =精餾產銷!K4 -> 耗用 | L4: =精餾產銷!L4 -> 銷售 | M4: =精餾產銷!M4 -> 耗用 | N4: =精餾產銷!N4 -> 銷售 | O4: =精餾產銷!O4 -> 耗用 | P4: =精餾產銷!P4 -> 24~31 | R4: =精餾產銷!R4 -> 數量 | S4: =精餾產銷!S4 -> 9月 | U4: =精餾產銷!U4 -> 數量 | V4: =精餾產銷!V4 -> 10月 | X4: =精餾產銷!X4 -> 數量 | Y4: =精餾產銷!Y4 -> 11月 | AA4: =精餾產銷!AA4 -> 數量 | AB4: =精餾產銷!AB4 -> 8/31 | AC4: =精餾產銷!AC4 -> 46295 | AD4: =精餾產銷!AD4 -> 46326 | AE4: =精餾產銷!AE4 -> 46356 | AH4: 最高 | AI4: 最低
D5: 0 | G5: =+D5+E5-F5 -> 0 | H5: 0 | J5: 0 | L5: 0 | N5: 0 | P5: =+IF(R5=0,0,"參配") -> 0 | Q5: =+IF(R5=0,0,P$4) -> 0 | S5: =+IF(U5=0,0,"參配") -> 0 | T5: =+IF(U5=0,0,S$4) -> 0 | V5: =+IF(X5=0,0,"參配") -> 0 | W5: =+IF(X5=0,0,V$4) -> 0 | Y5: =+IF(AA5=0,0,"參配") -> 0 | Z5: =+IF(AA5=0,0,Y$4) -> 0 | AB5: =+G5-SUM(H5:I5)+SUM(R5:R5) -> 0 | AC5: =+AB5-SUM(J5:K5)+SUM(U5:U5) -> 0 | AD5: =+AC5-SUM(L5:M5)+SUM(X5:X5) -> 0 | AE5: =+AD5-SUM(N5:O5)+SUM(AA5:AA5) -> 0 | AF5: =+IF(SUM(G5,H5:O5,R5,U5,X5,AA5)=0,0,1) -> 0
A6: NSE-115 | B6: TKM82&200L | C6: 170 | D6: 157.586 | G6: =IF(+D6+E6-F6<=0,0,+D6+E6-F6) -> 157.586 | H6: 29 | J6: 110 | L6: 110 | N6: 110 | P6: =+IF(R6=0,0,"參配") -> 參配 | Q6: =+IF(R6=0,0,P$4) -> 24~31 | R6: 26.3 | S6: =+IF(U6=0,0,"參配") -> 參配 | T6: =+IF(U6=0,0,S$4) -> 9月 | U6: 114 | V6: =+IF(X6=0,0,"參配") -> 參配 | W6: =+IF(X6=0,0,V$4) -> 10月 | X6: 114 | Y6: =+IF(AA6=0,0,"參配") -> 參配 | Z6: =+IF(AA6=0,0,Y$4) -> 11月 | AA6: 114 | AB6: =+G6-SUM(H6:I6)+SUM(R6:R6) -> 154.886 | AC6: =+AB6-SUM(J6:K6)+SUM(U6:U6) -> 158.886 | AD6: =+AC6-SUM(L6:M6)+SUM(X6:X6) -> 162.886 | AE6: =+AD6-SUM(N6:O6)+SUM(AA6:AA6) -> 166.886 | AF6: =+IF(SUM(G6,H6:O6,R6,U6,X6,AA6)=0,0,1) -> 1 | AI6: 315
